2020-08-21 00:41:21,595 (67567/MainThread) pgcli.main INFO - Default pager found in PAGER environment variable: "less"
2020-08-21 00:41:21,595 (67567/MainThread) pgcli.main WARNING - import keyring failed: ModuleNotFoundError("No module named 'keyring'").
2020-08-21 00:41:21,601 (67567/MainThread) pgcli.main ERROR - traceback: 'Traceback (most recent call last):\n  File "/usr/local/Cellar/pgcli/3.0.0/libexec/lib/python3.8/site-packages/pgcli/main.py", line 562, in connect\n    raise e\n  File "/usr/local/Cellar/pgcli/3.0.0/libexec/lib/python3.8/site-packages/pgcli/main.py", line 549, in connect\n    pgexecute = PGExecute(database, user, passwd, host, port, dsn, **kwargs)\n  File "/usr/local/Cellar/pgcli/3.0.0/libexec/lib/python3.8/site-packages/pgcli/pgexecute.py", line 214, in __init__\n    self.connect(database, user, password, host, port, dsn, **kwargs)\n  File "/usr/local/Cellar/pgcli/3.0.0/libexec/lib/python3.8/site-packages/pgcli/pgexecute.py", line 254, in connect\n    conn = psycopg2.connect(**conn_params)\n  File "/usr/local/Cellar/pgcli/3.0.0/libexec/lib/python3.8/site-packages/psycopg2/__init__.py", line 127, in connect\n    conn = _connect(dsn, connection_factory=connection_factory, **kwasync)\npsycopg2.OperationalError: could not connect to server: No such file or directory\n\tIs the server running locally and accepting\n\tconnections on Unix domain socket "/tmp/.s.PGSQL.5432"?\n\n'
2020-09-11 11:35:27,497 (76628/MainThread) pgcli.main INFO - Default pager found in PAGER environment variable: "less"
2020-09-11 11:35:27,498 (76628/MainThread) pgcli.main WARNING - import keyring failed: ModuleNotFoundError("No module named 'keyring'").
2020-09-11 11:35:29,394 (76628/MainThread) pgcli.main ERROR - traceback: 'Traceback (most recent call last):\n  File "/usr/local/Cellar/pgcli/3.0.0/libexec/lib/python3.8/site-packages/pgcli/main.py", line 562, in connect\n    raise e\n  File "/usr/local/Cellar/pgcli/3.0.0/libexec/lib/python3.8/site-packages/pgcli/main.py", line 549, in connect\n    pgexecute = PGExecute(database, user, passwd, host, port, dsn, **kwargs)\n  File "/usr/local/Cellar/pgcli/3.0.0/libexec/lib/python3.8/site-packages/pgcli/pgexecute.py", line 214, in __init__\n    self.connect(database, user, password, host, port, dsn, **kwargs)\n  File "/usr/local/Cellar/pgcli/3.0.0/libexec/lib/python3.8/site-packages/pgcli/pgexecute.py", line 254, in connect\n    conn = psycopg2.connect(**conn_params)\n  File "/usr/local/Cellar/pgcli/3.0.0/libexec/lib/python3.8/site-packages/psycopg2/__init__.py", line 127, in connect\n    conn = _connect(dsn, connection_factory=connection_factory, **kwasync)\n  File "/usr/local/Cellar/pgcli/3.0.0/libexec/lib/python3.8/site-packages/pgcli/pgexecute.py", line 39, in _wait_select\n    state = conn.poll()\npsycopg2.OperationalError: fe_sendauth: no password supplied\n\n'
2020-09-11 11:35:32,701 (76870/MainThread) pgcli.main INFO - Default pager found in PAGER environment variable: "less"
2020-09-11 11:35:32,702 (76870/MainThread) pgcli.main WARNING - import keyring failed: ModuleNotFoundError("No module named 'keyring'").
2020-09-11 11:35:34,260 (76870/MainThread) pgcli.main ERROR - traceback: 'Traceback (most recent call last):\n  File "/usr/local/Cellar/pgcli/3.0.0/libexec/lib/python3.8/site-packages/pgcli/main.py", line 562, in connect\n    raise e\n  File "/usr/local/Cellar/pgcli/3.0.0/libexec/lib/python3.8/site-packages/pgcli/main.py", line 549, in connect\n    pgexecute = PGExecute(database, user, passwd, host, port, dsn, **kwargs)\n  File "/usr/local/Cellar/pgcli/3.0.0/libexec/lib/python3.8/site-packages/pgcli/pgexecute.py", line 214, in __init__\n    self.connect(database, user, password, host, port, dsn, **kwargs)\n  File "/usr/local/Cellar/pgcli/3.0.0/libexec/lib/python3.8/site-packages/pgcli/pgexecute.py", line 254, in connect\n    conn = psycopg2.connect(**conn_params)\n  File "/usr/local/Cellar/pgcli/3.0.0/libexec/lib/python3.8/site-packages/psycopg2/__init__.py", line 127, in connect\n    conn = _connect(dsn, connection_factory=connection_factory, **kwasync)\n  File "/usr/local/Cellar/pgcli/3.0.0/libexec/lib/python3.8/site-packages/pgcli/pgexecute.py", line 39, in _wait_select\n    state = conn.poll()\npsycopg2.OperationalError: fe_sendauth: no password supplied\n\n'
2020-09-11 11:35:43,442 (77212/MainThread) pgcli.main INFO - Default pager found in PAGER environment variable: "less"
2020-09-11 11:35:43,442 (77212/MainThread) pgcli.main WARNING - import keyring failed: ModuleNotFoundError("No module named 'keyring'").
2020-09-11 11:35:45,114 (77212/MainThread) pgcli.main ERROR - traceback: 'Traceback (most recent call last):\n  File "/usr/local/Cellar/pgcli/3.0.0/libexec/lib/python3.8/site-packages/pgcli/main.py", line 562, in connect\n    raise e\n  File "/usr/local/Cellar/pgcli/3.0.0/libexec/lib/python3.8/site-packages/pgcli/main.py", line 549, in connect\n    pgexecute = PGExecute(database, user, passwd, host, port, dsn, **kwargs)\n  File "/usr/local/Cellar/pgcli/3.0.0/libexec/lib/python3.8/site-packages/pgcli/pgexecute.py", line 214, in __init__\n    self.connect(database, user, password, host, port, dsn, **kwargs)\n  File "/usr/local/Cellar/pgcli/3.0.0/libexec/lib/python3.8/site-packages/pgcli/pgexecute.py", line 254, in connect\n    conn = psycopg2.connect(**conn_params)\n  File "/usr/local/Cellar/pgcli/3.0.0/libexec/lib/python3.8/site-packages/psycopg2/__init__.py", line 127, in connect\n    conn = _connect(dsn, connection_factory=connection_factory, **kwasync)\n  File "/usr/local/Cellar/pgcli/3.0.0/libexec/lib/python3.8/site-packages/pgcli/pgexecute.py", line 39, in _wait_select\n    state = conn.poll()\npsycopg2.OperationalError: fe_sendauth: no password supplied\n\n'
2020-09-11 11:35:54,237 (77548/MainThread) pgcli.main INFO - Default pager found in PAGER environment variable: "less"
2020-09-11 11:35:54,237 (77548/MainThread) pgcli.main WARNING - import keyring failed: ModuleNotFoundError("No module named 'keyring'").
2020-09-11 11:36:10,327 (77548/MainThread) pgcli.main ERROR - traceback: 'Traceback (most recent call last):\n  File "/usr/local/Cellar/pgcli/3.0.0/libexec/lib/python3.8/site-packages/pgcli/main.py", line 562, in connect\n    raise e\n  File "/usr/local/Cellar/pgcli/3.0.0/libexec/lib/python3.8/site-packages/pgcli/main.py", line 549, in connect\n    pgexecute = PGExecute(database, user, passwd, host, port, dsn, **kwargs)\n  File "/usr/local/Cellar/pgcli/3.0.0/libexec/lib/python3.8/site-packages/pgcli/pgexecute.py", line 214, in __init__\n    self.connect(database, user, password, host, port, dsn, **kwargs)\n  File "/usr/local/Cellar/pgcli/3.0.0/libexec/lib/python3.8/site-packages/pgcli/pgexecute.py", line 254, in connect\n    conn = psycopg2.connect(**conn_params)\n  File "/usr/local/Cellar/pgcli/3.0.0/libexec/lib/python3.8/site-packages/psycopg2/__init__.py", line 127, in connect\n    conn = _connect(dsn, connection_factory=connection_factory, **kwasync)\n  File "/usr/local/Cellar/pgcli/3.0.0/libexec/lib/python3.8/site-packages/pgcli/pgexecute.py", line 39, in _wait_select\n    state = conn.poll()\npsycopg2.OperationalError: FATAL:  database "Komi123!" does not exist\n\n'
2020-09-11 11:36:16,772 (78242/MainThread) pgcli.main INFO - Default pager found in PAGER environment variable: "less"
2020-09-11 11:36:16,772 (78242/MainThread) pgcli.main WARNING - import keyring failed: ModuleNotFoundError("No module named 'keyring'").
2020-09-11 11:36:25,050 (78242/MainThread) pgcli.main ERROR - traceback: 'Traceback (most recent call last):\n  File "/usr/local/Cellar/pgcli/3.0.0/libexec/lib/python3.8/site-packages/pgcli/main.py", line 549, in connect\n    pgexecute = PGExecute(database, user, passwd, host, port, dsn, **kwargs)\n  File "/usr/local/Cellar/pgcli/3.0.0/libexec/lib/python3.8/site-packages/pgcli/pgexecute.py", line 214, in __init__\n    self.connect(database, user, password, host, port, dsn, **kwargs)\n  File "/usr/local/Cellar/pgcli/3.0.0/libexec/lib/python3.8/site-packages/pgcli/pgexecute.py", line 254, in connect\n    conn = psycopg2.connect(**conn_params)\n  File "/usr/local/Cellar/pgcli/3.0.0/libexec/lib/python3.8/site-packages/psycopg2/__init__.py", line 127, in connect\n    conn = _connect(dsn, connection_factory=connection_factory, **kwasync)\n  File "/usr/local/Cellar/pgcli/3.0.0/libexec/lib/python3.8/site-packages/pgcli/pgexecute.py", line 39, in _wait_select\n    state = conn.poll()\npsycopg2.OperationalError: FATAL:  password authentication failed for user "postgres"\nFATAL:  password authentication failed for user "postgres"\n\n\nDuring handling of the above exception, another exception occurred:\n\nTraceback (most recent call last):\n  File "/usr/local/Cellar/pgcli/3.0.0/libexec/lib/python3.8/site-packages/pgcli/main.py", line 558, in connect\n    pgexecute = PGExecute(\n  File "/usr/local/Cellar/pgcli/3.0.0/libexec/lib/python3.8/site-packages/pgcli/pgexecute.py", line 214, in __init__\n    self.connect(database, user, password, host, port, dsn, **kwargs)\n  File "/usr/local/Cellar/pgcli/3.0.0/libexec/lib/python3.8/site-packages/pgcli/pgexecute.py", line 254, in connect\n    conn = psycopg2.connect(**conn_params)\n  File "/usr/local/Cellar/pgcli/3.0.0/libexec/lib/python3.8/site-packages/psycopg2/__init__.py", line 127, in connect\n    conn = _connect(dsn, connection_factory=connection_factory, **kwasync)\n  File "/usr/local/Cellar/pgcli/3.0.0/libexec/lib/python3.8/site-packages/pgcli/pgexecute.py", line 39, in _wait_select\n    state = conn.poll()\npsycopg2.OperationalError: FATAL:  password authentication failed for user "postgres"\nFATAL:  password authentication failed for user "postgres"\n\n'
2020-09-11 11:36:38,416 (78819/MainThread) pgcli.main INFO - Default pager found in PAGER environment variable: "less"
2020-09-11 11:36:38,417 (78819/MainThread) pgcli.main WARNING - import keyring failed: ModuleNotFoundError("No module named 'keyring'").
2020-09-11 11:36:45,223 (78819/MainThread) pgcli.main ERROR - traceback: 'Traceback (most recent call last):\n  File "/usr/local/Cellar/pgcli/3.0.0/libexec/lib/python3.8/site-packages/pgcli/main.py", line 549, in connect\n    pgexecute = PGExecute(database, user, passwd, host, port, dsn, **kwargs)\n  File "/usr/local/Cellar/pgcli/3.0.0/libexec/lib/python3.8/site-packages/pgcli/pgexecute.py", line 214, in __init__\n    self.connect(database, user, password, host, port, dsn, **kwargs)\n  File "/usr/local/Cellar/pgcli/3.0.0/libexec/lib/python3.8/site-packages/pgcli/pgexecute.py", line 254, in connect\n    conn = psycopg2.connect(**conn_params)\n  File "/usr/local/Cellar/pgcli/3.0.0/libexec/lib/python3.8/site-packages/psycopg2/__init__.py", line 127, in connect\n    conn = _connect(dsn, connection_factory=connection_factory, **kwasync)\n  File "/usr/local/Cellar/pgcli/3.0.0/libexec/lib/python3.8/site-packages/pgcli/pgexecute.py", line 39, in _wait_select\n    state = conn.poll()\npsycopg2.OperationalError: fe_sendauth: no password supplied\n\n\nDuring handling of the above exception, another exception occurred:\n\nTraceback (most recent call last):\n  File "/usr/local/Cellar/pgcli/3.0.0/libexec/lib/python3.8/site-packages/pgcli/main.py", line 558, in connect\n    pgexecute = PGExecute(\n  File "/usr/local/Cellar/pgcli/3.0.0/libexec/lib/python3.8/site-packages/pgcli/pgexecute.py", line 214, in __init__\n    self.connect(database, user, password, host, port, dsn, **kwargs)\n  File "/usr/local/Cellar/pgcli/3.0.0/libexec/lib/python3.8/site-packages/pgcli/pgexecute.py", line 254, in connect\n    conn = psycopg2.connect(**conn_params)\n  File "/usr/local/Cellar/pgcli/3.0.0/libexec/lib/python3.8/site-packages/psycopg2/__init__.py", line 127, in connect\n    conn = _connect(dsn, connection_factory=connection_factory, **kwasync)\n  File "/usr/local/Cellar/pgcli/3.0.0/libexec/lib/python3.8/site-packages/pgcli/pgexecute.py", line 39, in _wait_select\n    state = conn.poll()\npsycopg2.OperationalError: FATAL:  database "Komi" does not exist\n\n'
2020-09-11 11:36:51,663 (79331/MainThread) pgcli.main INFO - Default pager found in PAGER environment variable: "less"
2020-09-11 11:36:51,663 (79331/MainThread) pgcli.main WARNING - import keyring failed: ModuleNotFoundError("No module named 'keyring'").
2020-09-11 11:36:53,145 (79331/MainThread) pgcli.main ERROR - traceback: 'Traceback (most recent call last):\n  File "/usr/local/Cellar/pgcli/3.0.0/libexec/lib/python3.8/site-packages/pgcli/main.py", line 549, in connect\n    pgexecute = PGExecute(database, user, passwd, host, port, dsn, **kwargs)\n  File "/usr/local/Cellar/pgcli/3.0.0/libexec/lib/python3.8/site-packages/pgcli/pgexecute.py", line 214, in __init__\n    self.connect(database, user, password, host, port, dsn, **kwargs)\n  File "/usr/local/Cellar/pgcli/3.0.0/libexec/lib/python3.8/site-packages/pgcli/pgexecute.py", line 254, in connect\n    conn = psycopg2.connect(**conn_params)\n  File "/usr/local/Cellar/pgcli/3.0.0/libexec/lib/python3.8/site-packages/psycopg2/__init__.py", line 127, in connect\n    conn = _connect(dsn, connection_factory=connection_factory, **kwasync)\n  File "/usr/local/Cellar/pgcli/3.0.0/libexec/lib/python3.8/site-packages/pgcli/pgexecute.py", line 39, in _wait_select\n    state = conn.poll()\npsycopg2.OperationalError: fe_sendauth: no password supplied\n\n\nDuring handling of the above exception, another exception occurred:\n\nTraceback (most recent call last):\n  File "/usr/local/Cellar/pgcli/3.0.0/libexec/lib/python3.8/site-packages/click/termui.py", line 129, in prompt_func\n    return f("")\n  File "/usr/local/Cellar/pgcli/3.0.0/libexec/lib/python3.8/site-packages/click/termui.py", line 54, in hidden_prompt_func\n    return getpass.getpass(prompt)\n  File "/usr/local/opt/python@3.8/Frameworks/Python.framework/Versions/3.8/lib/python3.8/getpass.py", line 76, in unix_getpass\n    termios.tcsetattr(fd, tcsetattr_flags, new)\nKeyboardInterrupt\n\nDuring handling of the above exception, another exception occurred:\n\nTraceback (most recent call last):\n  File "/usr/local/Cellar/pgcli/3.0.0/libexec/lib/python3.8/site-packages/pgcli/main.py", line 552, in connect\n    passwd = click.prompt(\n  File "/usr/local/Cellar/pgcli/3.0.0/libexec/lib/python3.8/site-packages/click/termui.py", line 147, in prompt\n    value = prompt_func(prompt)\n  File "/usr/local/Cellar/pgcli/3.0.0/libexec/lib/python3.8/site-packages/click/termui.py", line 136, in prompt_func\n    raise Abort()\nclick.exceptions.Abort\n'
2020-09-11 11:36:56,058 (79481/MainThread) pgcli.main INFO - Default pager found in PAGER environment variable: "less"
2020-09-11 11:36:56,058 (79481/MainThread) pgcli.main WARNING - import keyring failed: ModuleNotFoundError("No module named 'keyring'").
2020-09-11 11:37:46,764 (79481/MainThread) pgcli.pgexecute ERROR - sql: 'SELECT * FROM public.users WHERE email=\'ild+louis3@nucleusstudio.io"', error: SyntaxError('unterminated quoted string at or near "\'ild+louis3@nucleusstudio.io""\nLINE 1: SELECT * FROM public.users WHERE email=\'ild+louis3@nucleusst...\n                                               ^\n')
2020-09-11 11:37:46,765 (79481/MainThread) pgcli.pgexecute ERROR - traceback: 'Traceback (most recent call last):\n  File "/usr/local/Cellar/pgcli/3.0.0/libexec/lib/python3.8/site-packages/pgcli/pgexecute.py", line 409, in run\n    yield self.execute_normal_sql(sql) + (sql, True, False)\n  File "/usr/local/Cellar/pgcli/3.0.0/libexec/lib/python3.8/site-packages/pgcli/pgexecute.py", line 444, in execute_normal_sql\n    cur.execute(split_sql)\npsycopg2.errors.SyntaxError: unterminated quoted string at or near "\'ild+louis3@nucleusstudio.io""\nLINE 1: SELECT * FROM public.users WHERE email=\'ild+louis3@nucleusst...\n                                               ^\n\n'
2020-09-11 11:37:49,017 (79481/MainThread) pgcli.pgexecute ERROR - sql: "SELECT * FROM public.users WHERE email='ild+louis3@nucleusstudio.io", error: SyntaxError('unterminated quoted string at or near "\'ild+louis3@nucleusstudio.io"\nLINE 1: SELECT * FROM public.users WHERE email=\'ild+louis3@nucleusst...\n                                               ^\n')
2020-09-11 11:37:49,017 (79481/MainThread) pgcli.pgexecute ERROR - traceback: 'Traceback (most recent call last):\n  File "/usr/local/Cellar/pgcli/3.0.0/libexec/lib/python3.8/site-packages/pgcli/pgexecute.py", line 409, in run\n    yield self.execute_normal_sql(sql) + (sql, True, False)\n  File "/usr/local/Cellar/pgcli/3.0.0/libexec/lib/python3.8/site-packages/pgcli/pgexecute.py", line 444, in execute_normal_sql\n    cur.execute(split_sql)\npsycopg2.errors.SyntaxError: unterminated quoted string at or near "\'ild+louis3@nucleusstudio.io"\nLINE 1: SELECT * FROM public.users WHERE email=\'ild+louis3@nucleusst...\n                                               ^\n\n'
2020-09-11 11:53:27,921 (79481/MainThread) pgcli.pgexecute ERROR - sql: '\\dbb', error: SyntaxError('syntax error at or near "\\"\nLINE 1: \\dbb\n        ^\n')
2020-09-11 11:53:27,929 (79481/MainThread) pgcli.pgexecute ERROR - traceback: 'Traceback (most recent call last):\n  File "/usr/local/Cellar/pgcli/3.0.0/libexec/lib/python3.8/site-packages/pgcli/pgexecute.py", line 409, in run\n    yield self.execute_normal_sql(sql) + (sql, True, False)\n  File "/usr/local/Cellar/pgcli/3.0.0/libexec/lib/python3.8/site-packages/pgcli/pgexecute.py", line 444, in execute_normal_sql\n    cur.execute(split_sql)\npsycopg2.errors.SyntaxError: syntax error at or near "\\"\nLINE 1: \\dbb\n        ^\n\n'
2020-09-11 11:54:17,461 (79481/MainThread) pgcli.pgexecute ERROR - sql: 'VIEW public', error: SyntaxError('syntax error at or near "VIEW"\nLINE 1: VIEW public\n        ^\n')
2020-09-11 11:54:17,461 (79481/MainThread) pgcli.pgexecute ERROR - traceback: 'Traceback (most recent call last):\n  File "/usr/local/Cellar/pgcli/3.0.0/libexec/lib/python3.8/site-packages/pgcli/pgexecute.py", line 409, in run\n    yield self.execute_normal_sql(sql) + (sql, True, False)\n  File "/usr/local/Cellar/pgcli/3.0.0/libexec/lib/python3.8/site-packages/pgcli/pgexecute.py", line 444, in execute_normal_sql\n    cur.execute(split_sql)\npsycopg2.errors.SyntaxError: syntax error at or near "VIEW"\nLINE 1: VIEW public\n        ^\n\n'
2020-09-11 11:55:29,203 (12249/MainThread) pgcli.main INFO - Default pager found in PAGER environment variable: "less"
2020-09-11 11:55:29,204 (12249/MainThread) pgcli.main WARNING - import keyring failed: ModuleNotFoundError("No module named 'keyring'").
2020-09-11 11:55:36,097 (12249/MainThread) pgcli.main ERROR - traceback: 'Traceback (most recent call last):\n  File "/usr/local/Cellar/pgcli/3.0.0/libexec/lib/python3.8/site-packages/pgcli/main.py", line 549, in connect\n    pgexecute = PGExecute(database, user, passwd, host, port, dsn, **kwargs)\n  File "/usr/local/Cellar/pgcli/3.0.0/libexec/lib/python3.8/site-packages/pgcli/pgexecute.py", line 214, in __init__\n    self.connect(database, user, password, host, port, dsn, **kwargs)\n  File "/usr/local/Cellar/pgcli/3.0.0/libexec/lib/python3.8/site-packages/pgcli/pgexecute.py", line 254, in connect\n    conn = psycopg2.connect(**conn_params)\n  File "/usr/local/Cellar/pgcli/3.0.0/libexec/lib/python3.8/site-packages/psycopg2/__init__.py", line 127, in connect\n    conn = _connect(dsn, connection_factory=connection_factory, **kwasync)\n  File "/usr/local/Cellar/pgcli/3.0.0/libexec/lib/python3.8/site-packages/pgcli/pgexecute.py", line 39, in _wait_select\n    state = conn.poll()\npsycopg2.OperationalError: fe_sendauth: no password supplied\n\n\nDuring handling of the above exception, another exception occurred:\n\nTraceback (most recent call last):\n  File "/usr/local/Cellar/pgcli/3.0.0/libexec/lib/python3.8/site-packages/pgcli/main.py", line 558, in connect\n    pgexecute = PGExecute(\n  File "/usr/local/Cellar/pgcli/3.0.0/libexec/lib/python3.8/site-packages/pgcli/pgexecute.py", line 214, in __init__\n    self.connect(database, user, password, host, port, dsn, **kwargs)\n  File "/usr/local/Cellar/pgcli/3.0.0/libexec/lib/python3.8/site-packages/pgcli/pgexecute.py", line 254, in connect\n    conn = psycopg2.connect(**conn_params)\n  File "/usr/local/Cellar/pgcli/3.0.0/libexec/lib/python3.8/site-packages/psycopg2/__init__.py", line 127, in connect\n    conn = _connect(dsn, connection_factory=connection_factory, **kwasync)\n  File "/usr/local/Cellar/pgcli/3.0.0/libexec/lib/python3.8/site-packages/pgcli/pgexecute.py", line 39, in _wait_select\n    state = conn.poll()\npsycopg2.OperationalError: FATAL:  password authentication failed for user "postgres"\nFATAL:  password authentication failed for user "postgres"\n\n'
2020-09-11 11:55:37,956 (12487/MainThread) pgcli.main INFO - Default pager found in PAGER environment variable: "less"
2020-09-11 11:55:37,957 (12487/MainThread) pgcli.main WARNING - import keyring failed: ModuleNotFoundError("No module named 'keyring'").
2020-09-11 11:56:52,926 (12487/MainThread) pgcli.pgexecute ERROR - sql: "desc 'public.user'", error: SyntaxError('syntax error at or near "desc"\nLINE 1: desc \'public.user\'\n        ^\n')
2020-09-11 11:56:52,927 (12487/MainThread) pgcli.pgexecute ERROR - traceback: 'Traceback (most recent call last):\n  File "/usr/local/Cellar/pgcli/3.0.0/libexec/lib/python3.8/site-packages/pgcli/pgexecute.py", line 409, in run\n    yield self.execute_normal_sql(sql) + (sql, True, False)\n  File "/usr/local/Cellar/pgcli/3.0.0/libexec/lib/python3.8/site-packages/pgcli/pgexecute.py", line 444, in execute_normal_sql\n    cur.execute(split_sql)\npsycopg2.errors.SyntaxError: syntax error at or near "desc"\nLINE 1: desc \'public.user\'\n        ^\n\n'
2020-09-11 11:56:57,022 (12487/MainThread) pgcli.pgexecute ERROR - sql: 'desc public.user', error: SyntaxError('syntax error at or near "desc"\nLINE 1: desc public.user\n        ^\n')
2020-09-11 11:56:57,022 (12487/MainThread) pgcli.pgexecute ERROR - traceback: 'Traceback (most recent call last):\n  File "/usr/local/Cellar/pgcli/3.0.0/libexec/lib/python3.8/site-packages/pgcli/pgexecute.py", line 409, in run\n    yield self.execute_normal_sql(sql) + (sql, True, False)\n  File "/usr/local/Cellar/pgcli/3.0.0/libexec/lib/python3.8/site-packages/pgcli/pgexecute.py", line 444, in execute_normal_sql\n    cur.execute(split_sql)\npsycopg2.errors.SyntaxError: syntax error at or near "desc"\nLINE 1: desc public.user\n        ^\n\n'
2020-09-11 11:57:02,039 (12487/MainThread) pgcli.pgexecute ERROR - sql: 'desc pctfree', error: SyntaxError('syntax error at or near "desc"\nLINE 1: desc pctfree\n        ^\n')
2020-09-11 11:57:02,040 (12487/MainThread) pgcli.pgexecute ERROR - traceback: 'Traceback (most recent call last):\n  File "/usr/local/Cellar/pgcli/3.0.0/libexec/lib/python3.8/site-packages/pgcli/pgexecute.py", line 409, in run\n    yield self.execute_normal_sql(sql) + (sql, True, False)\n  File "/usr/local/Cellar/pgcli/3.0.0/libexec/lib/python3.8/site-packages/pgcli/pgexecute.py", line 444, in execute_normal_sql\n    cur.execute(split_sql)\npsycopg2.errors.SyntaxError: syntax error at or near "desc"\nLINE 1: desc pctfree\n        ^\n\n'
2020-09-11 12:09:04,778 (12487/MainThread) pgcli.pgexecute ERROR - sql: '/d', error: SyntaxError('syntax error at or near "/"\nLINE 1: /d\n        ^\n')
2020-09-11 12:09:04,780 (12487/MainThread) pgcli.pgexecute ERROR - traceback: 'Traceback (most recent call last):\n  File "/usr/local/Cellar/pgcli/3.0.0/libexec/lib/python3.8/site-packages/pgcli/pgexecute.py", line 409, in run\n    yield self.execute_normal_sql(sql) + (sql, True, False)\n  File "/usr/local/Cellar/pgcli/3.0.0/libexec/lib/python3.8/site-packages/pgcli/pgexecute.py", line 444, in execute_normal_sql\n    cur.execute(split_sql)\npsycopg2.errors.SyntaxError: syntax error at or near "/"\nLINE 1: /d\n        ^\n\n'
2020-09-11 12:09:16,349 (12487/MainThread) pgcli.pgexecute ERROR - sql: 'SELE', error: SyntaxError('syntax error at or near "SELE"\nLINE 1: SELE\n        ^\n')
2020-09-11 12:09:16,350 (12487/MainThread) pgcli.pgexecute ERROR - traceback: 'Traceback (most recent call last):\n  File "/usr/local/Cellar/pgcli/3.0.0/libexec/lib/python3.8/site-packages/pgcli/pgexecute.py", line 409, in run\n    yield self.execute_normal_sql(sql) + (sql, True, False)\n  File "/usr/local/Cellar/pgcli/3.0.0/libexec/lib/python3.8/site-packages/pgcli/pgexecute.py", line 444, in execute_normal_sql\n    cur.execute(split_sql)\npsycopg2.errors.SyntaxError: syntax error at or near "SELE"\nLINE 1: SELE\n        ^\n\n'
2020-09-11 12:09:36,368 (33831/MainThread) pgcli.main INFO - Default pager found in PAGER environment variable: "less"
2020-09-11 12:09:36,368 (33831/MainThread) pgcli.main WARNING - import keyring failed: ModuleNotFoundError("No module named 'keyring'").
2020-09-11 15:03:55,785 (99801/MainThread) pgcli.main INFO - Default pager found in PAGER environment variable: "less"
2020-09-11 15:03:55,787 (99801/MainThread) pgcli.main WARNING - import keyring failed: ModuleNotFoundError("No module named 'keyring'").
2020-09-11 15:04:02,904 (99801/MainThread) pgcli.main ERROR - traceback: 'Traceback (most recent call last):\n  File "/usr/local/Cellar/pgcli/3.0.0/libexec/lib/python3.8/site-packages/pgcli/main.py", line 549, in connect\n    pgexecute = PGExecute(database, user, passwd, host, port, dsn, **kwargs)\n  File "/usr/local/Cellar/pgcli/3.0.0/libexec/lib/python3.8/site-packages/pgcli/pgexecute.py", line 214, in __init__\n    self.connect(database, user, password, host, port, dsn, **kwargs)\n  File "/usr/local/Cellar/pgcli/3.0.0/libexec/lib/python3.8/site-packages/pgcli/pgexecute.py", line 254, in connect\n    conn = psycopg2.connect(**conn_params)\n  File "/usr/local/Cellar/pgcli/3.0.0/libexec/lib/python3.8/site-packages/psycopg2/__init__.py", line 127, in connect\n    conn = _connect(dsn, connection_factory=connection_factory, **kwasync)\n  File "/usr/local/Cellar/pgcli/3.0.0/libexec/lib/python3.8/site-packages/pgcli/pgexecute.py", line 39, in _wait_select\n    state = conn.poll()\npsycopg2.OperationalError: fe_sendauth: no password supplied\n\n\nDuring handling of the above exception, another exception occurred:\n\nTraceback (most recent call last):\n  File "/usr/local/Cellar/pgcli/3.0.0/libexec/lib/python3.8/site-packages/pgcli/main.py", line 558, in connect\n    pgexecute = PGExecute(\n  File "/usr/local/Cellar/pgcli/3.0.0/libexec/lib/python3.8/site-packages/pgcli/pgexecute.py", line 214, in __init__\n    self.connect(database, user, password, host, port, dsn, **kwargs)\n  File "/usr/local/Cellar/pgcli/3.0.0/libexec/lib/python3.8/site-packages/pgcli/pgexecute.py", line 254, in connect\n    conn = psycopg2.connect(**conn_params)\n  File "/usr/local/Cellar/pgcli/3.0.0/libexec/lib/python3.8/site-packages/psycopg2/__init__.py", line 127, in connect\n    conn = _connect(dsn, connection_factory=connection_factory, **kwasync)\n  File "/usr/local/Cellar/pgcli/3.0.0/libexec/lib/python3.8/site-packages/pgcli/pgexecute.py", line 39, in _wait_select\n    state = conn.poll()\npsycopg2.OperationalError: FATAL:  password authentication failed for user "postgres"\nFATAL:  password authentication failed for user "postgres"\n\n'
2020-09-11 15:04:07,134 (172/MainThread) pgcli.main INFO - Default pager found in PAGER environment variable: "less"
2020-09-11 15:04:07,135 (172/MainThread) pgcli.main WARNING - import keyring failed: ModuleNotFoundError("No module named 'keyring'").
2020-09-11 17:14:43,882 (172/MainThread) pgcli.pgexecute ERROR - sql: 'c', error: SyntaxError('syntax error at or near "c"\nLINE 1: c\n        ^\n')
2020-09-11 17:14:43,891 (172/MainThread) pgcli.pgexecute ERROR - traceback: 'Traceback (most recent call last):\n  File "/usr/local/Cellar/pgcli/3.0.0/libexec/lib/python3.8/site-packages/pgcli/pgexecute.py", line 409, in run\n    yield self.execute_normal_sql(sql) + (sql, True, False)\n  File "/usr/local/Cellar/pgcli/3.0.0/libexec/lib/python3.8/site-packages/pgcli/pgexecute.py", line 444, in execute_normal_sql\n    cur.execute(split_sql)\npsycopg2.errors.SyntaxError: syntax error at or near "c"\nLINE 1: c\n        ^\n\n'
2020-09-11 17:14:50,153 (172/MainThread) pgcli.pgexecute ERROR - sql: 'clear', error: SyntaxError('syntax error at or near "clear"\nLINE 1: clear\n        ^\n')
2020-09-11 17:14:50,154 (172/MainThread) pgcli.pgexecute ERROR - traceback: 'Traceback (most recent call last):\n  File "/usr/local/Cellar/pgcli/3.0.0/libexec/lib/python3.8/site-packages/pgcli/pgexecute.py", line 409, in run\n    yield self.execute_normal_sql(sql) + (sql, True, False)\n  File "/usr/local/Cellar/pgcli/3.0.0/libexec/lib/python3.8/site-packages/pgcli/pgexecute.py", line 444, in execute_normal_sql\n    cur.execute(split_sql)\npsycopg2.errors.SyntaxError: syntax error at or near "clear"\nLINE 1: clear\n        ^\n\n'
2020-09-11 17:14:53,359 (172/MainThread) pgcli.pgexecute ERROR - sql: 'c', error: SyntaxError('syntax error at or near "c"\nLINE 1: c\n        ^\n')
2020-09-11 17:14:53,359 (172/MainThread) pgcli.pgexecute ERROR - traceback: 'Traceback (most recent call last):\n  File "/usr/local/Cellar/pgcli/3.0.0/libexec/lib/python3.8/site-packages/pgcli/pgexecute.py", line 409, in run\n    yield self.execute_normal_sql(sql) + (sql, True, False)\n  File "/usr/local/Cellar/pgcli/3.0.0/libexec/lib/python3.8/site-packages/pgcli/pgexecute.py", line 444, in execute_normal_sql\n    cur.execute(split_sql)\npsycopg2.errors.SyntaxError: syntax error at or near "c"\nLINE 1: c\n        ^\n\n'
2020-09-11 17:15:03,250 (85313/MainThread) pgcli.main INFO - Default pager found in PAGER environment variable: "less"
2020-09-11 17:15:03,251 (85313/MainThread) pgcli.main WARNING - import keyring failed: ModuleNotFoundError("No module named 'keyring'").
2020-09-11 17:15:07,344 (85313/MainThread) pgcli.main ERROR - traceback: 'Traceback (most recent call last):\n  File "/usr/local/Cellar/pgcli/3.0.0/libexec/lib/python3.8/site-packages/pgcli/main.py", line 549, in connect\n    pgexecute = PGExecute(database, user, passwd, host, port, dsn, **kwargs)\n  File "/usr/local/Cellar/pgcli/3.0.0/libexec/lib/python3.8/site-packages/pgcli/pgexecute.py", line 214, in __init__\n    self.connect(database, user, password, host, port, dsn, **kwargs)\n  File "/usr/local/Cellar/pgcli/3.0.0/libexec/lib/python3.8/site-packages/pgcli/pgexecute.py", line 254, in connect\n    conn = psycopg2.connect(**conn_params)\n  File "/usr/local/Cellar/pgcli/3.0.0/libexec/lib/python3.8/site-packages/psycopg2/__init__.py", line 127, in connect\n    conn = _connect(dsn, connection_factory=connection_factory, **kwasync)\n  File "/usr/local/Cellar/pgcli/3.0.0/libexec/lib/python3.8/site-packages/pgcli/pgexecute.py", line 39, in _wait_select\n    state = conn.poll()\npsycopg2.OperationalError: fe_sendauth: no password supplied\n\n\nDuring handling of the above exception, another exception occurred:\n\nTraceback (most recent call last):\n  File "/usr/local/Cellar/pgcli/3.0.0/libexec/lib/python3.8/site-packages/click/termui.py", line 129, in prompt_func\n    return f("")\n  File "/usr/local/Cellar/pgcli/3.0.0/libexec/lib/python3.8/site-packages/click/termui.py", line 54, in hidden_prompt_func\n    return getpass.getpass(prompt)\n  File "/usr/local/opt/python@3.8/Frameworks/Python.framework/Versions/3.8/lib/python3.8/getpass.py", line 77, in unix_getpass\n    passwd = _raw_input(prompt, stream, input=input)\n  File "/usr/local/opt/python@3.8/Frameworks/Python.framework/Versions/3.8/lib/python3.8/getpass.py", line 146, in _raw_input\n    line = input.readline()\nKeyboardInterrupt\n\nDuring handling of the above exception, another exception occurred:\n\nTraceback (most recent call last):\n  File "/usr/local/Cellar/pgcli/3.0.0/libexec/lib/python3.8/site-packages/pgcli/main.py", line 552, in connect\n    passwd = click.prompt(\n  File "/usr/local/Cellar/pgcli/3.0.0/libexec/lib/python3.8/site-packages/click/termui.py", line 147, in prompt\n    value = prompt_func(prompt)\n  File "/usr/local/Cellar/pgcli/3.0.0/libexec/lib/python3.8/site-packages/click/termui.py", line 136, in prompt_func\n    raise Abort()\nclick.exceptions.Abort\n'
2020-09-11 17:15:09,219 (85612/MainThread) pgcli.main INFO - Default pager found in PAGER environment variable: "less"
2020-09-11 17:15:09,220 (85612/MainThread) pgcli.main WARNING - import keyring failed: ModuleNotFoundError("No module named 'keyring'").
2020-09-11 17:15:31,620 (85612/MainThread) pgcli.pgexecute ERROR - sql: 'SET talent_profile_id=null', error: SyntaxError('syntax error at or near "null"\nLINE 1: SET talent_profile_id=null\n                              ^\n')
2020-09-11 17:15:31,621 (85612/MainThread) pgcli.pgexecute ERROR - traceback: 'Traceback (most recent call last):\n  File "/usr/local/Cellar/pgcli/3.0.0/libexec/lib/python3.8/site-packages/pgcli/pgexecute.py", line 409, in run\n    yield self.execute_normal_sql(sql) + (sql, True, False)\n  File "/usr/local/Cellar/pgcli/3.0.0/libexec/lib/python3.8/site-packages/pgcli/pgexecute.py", line 444, in execute_normal_sql\n    cur.execute(split_sql)\npsycopg2.errors.SyntaxError: syntax error at or near "null"\nLINE 1: SET talent_profile_id=null\n                              ^\n\n'
2020-09-11 17:24:21,718 (85612/MainThread) pgcli.pgexecute ERROR - sql: "UPDATE public.talent_profiles SET status='completed' where id=''e4bca440-7cf7-4506-aa7f-96afbd78dbb3'", error: SyntaxError('syntax error at or near "e4bca440"\nLINE 1: ...talent_profiles SET status=\'completed\' where id=\'\'e4bca440-7...\n                                                             ^\n')
2020-09-11 17:24:21,718 (85612/MainThread) pgcli.pgexecute ERROR - traceback: 'Traceback (most recent call last):\n  File "/usr/local/Cellar/pgcli/3.0.0/libexec/lib/python3.8/site-packages/pgcli/pgexecute.py", line 409, in run\n    yield self.execute_normal_sql(sql) + (sql, True, False)\n  File "/usr/local/Cellar/pgcli/3.0.0/libexec/lib/python3.8/site-packages/pgcli/pgexecute.py", line 444, in execute_normal_sql\n    cur.execute(split_sql)\npsycopg2.errors.SyntaxError: syntax error at or near "e4bca440"\nLINE 1: ...talent_profiles SET status=\'completed\' where id=\'\'e4bca440-7...\n                                                             ^\n\n'
2020-09-11 18:15:42,865 (85612/MainThread) pgcli.pgexecute ERROR - sql: "UPDATE public.users as us join public.talent_profiles as tp on us.talent_profile_id = tp.id set tp.status = 'completed'", error: SyntaxError('syntax error at or near "join"\nLINE 1: UPDATE public.users as us join public.talent_profiles as tp ...\n                                  ^\n')
2020-09-11 18:15:42,871 (85612/MainThread) pgcli.pgexecute ERROR - traceback: 'Traceback (most recent call last):\n  File "/usr/local/Cellar/pgcli/3.0.0/libexec/lib/python3.8/site-packages/pgcli/pgexecute.py", line 409, in run\n    yield self.execute_normal_sql(sql) + (sql, True, False)\n  File "/usr/local/Cellar/pgcli/3.0.0/libexec/lib/python3.8/site-packages/pgcli/pgexecute.py", line 444, in execute_normal_sql\n    cur.execute(split_sql)\npsycopg2.errors.SyntaxError: syntax error at or near "join"\nLINE 1: UPDATE public.users as us join public.talent_profiles as tp ...\n                                  ^\n\n'
2020-09-11 18:15:54,313 (85612/MainThread) pgcli.pgexecute ERROR - sql: "UPDATE public.users as us JOIN public.talent_profiles as tp on us.talent_profile_id = tp.id set tp.status = 'completed'", error: SyntaxError('syntax error at or near "JOIN"\nLINE 1: UPDATE public.users as us JOIN public.talent_profiles as tp ...\n                                  ^\n')
2020-09-11 18:15:54,314 (85612/MainThread) pgcli.pgexecute ERROR - traceback: 'Traceback (most recent call last):\n  File "/usr/local/Cellar/pgcli/3.0.0/libexec/lib/python3.8/site-packages/pgcli/pgexecute.py", line 409, in run\n    yield self.execute_normal_sql(sql) + (sql, True, False)\n  File "/usr/local/Cellar/pgcli/3.0.0/libexec/lib/python3.8/site-packages/pgcli/pgexecute.py", line 444, in execute_normal_sql\n    cur.execute(split_sql)\npsycopg2.errors.SyntaxError: syntax error at or near "JOIN"\nLINE 1: UPDATE public.users as us JOIN public.talent_profiles as tp ...\n                                  ^\n\n'
2020-09-11 18:18:14,380 (85612/MainThread) pgcli.pgexecute ERROR - sql: "UPDATE public.applications SET status = 'completed' WHERE id = 'bc9c56c4-feb8-4b54-b18a-c4f2751f3b49'", error: UndefinedColumn('column "status" of relation "applications" does not exist\nLINE 1: UPDATE public.applications SET status = \'completed\' WHERE id...\n                                       ^\n')
2020-09-11 18:18:14,380 (85612/MainThread) pgcli.pgexecute ERROR - traceback: 'Traceback (most recent call last):\n  File "/usr/local/Cellar/pgcli/3.0.0/libexec/lib/python3.8/site-packages/pgcli/pgexecute.py", line 409, in run\n    yield self.execute_normal_sql(sql) + (sql, True, False)\n  File "/usr/local/Cellar/pgcli/3.0.0/libexec/lib/python3.8/site-packages/pgcli/pgexecute.py", line 444, in execute_normal_sql\n    cur.execute(split_sql)\npsycopg2.errors.UndefinedColumn: column "status" of relation "applications" does not exist\nLINE 1: UPDATE public.applications SET status = \'completed\' WHERE id...\n                                       ^\n\n'
2020-09-11 18:18:29,627 (85612/MainThread) pgcli.pgexecute ERROR - sql: "UPDATE public.applications SET status='completed' WHERE id='bc9c56c4-feb8-4b54-b18a-c4f2751f3b49'", error: UndefinedColumn('column "status" of relation "applications" does not exist\nLINE 1: UPDATE public.applications SET status=\'completed\' WHERE id=\'...\n                                       ^\n')
2020-09-11 18:18:29,628 (85612/MainThread) pgcli.pgexecute ERROR - traceback: 'Traceback (most recent call last):\n  File "/usr/local/Cellar/pgcli/3.0.0/libexec/lib/python3.8/site-packages/pgcli/pgexecute.py", line 409, in run\n    yield self.execute_normal_sql(sql) + (sql, True, False)\n  File "/usr/local/Cellar/pgcli/3.0.0/libexec/lib/python3.8/site-packages/pgcli/pgexecute.py", line 444, in execute_normal_sql\n    cur.execute(split_sql)\npsycopg2.errors.UndefinedColumn: column "status" of relation "applications" does not exist\nLINE 1: UPDATE public.applications SET status=\'completed\' WHERE id=\'...\n                                       ^\n\n'
2020-09-11 23:11:40,477 (85612/MainThread) pgcli.pgexecute ERROR - sql: '\\d', error: OperationalError('server closed the connection unexpectedly\n\tThis probably means the server terminated abnormally\n\tbefore or while processing the request.\n')
2020-09-11 23:11:40,486 (85612/MainThread) pgcli.pgexecute ERROR - traceback: 'Traceback (most recent call last):\n  File "/usr/local/Cellar/pgcli/3.0.0/libexec/lib/python3.8/site-packages/pgcli/pgexecute.py", line 398, in run\n    for result in pgspecial.execute(cur, sql):\n  File "/usr/local/Cellar/pgcli/3.0.0/libexec/lib/python3.8/site-packages/pgspecial/main.py", line 90, in execute\n    return special_cmd.handler(cur=cur, pattern=pattern, verbose=verbose)\n  File "/usr/local/Cellar/pgcli/3.0.0/libexec/lib/python3.8/site-packages/pgspecial/dbcommands.py", line 684, in describe_table_details\n    return list_objects(cur, pattern, verbose, [\'r\', \'p\', \'v\', \'m\', \'S\', \'f\', \'\'])\n  File "/usr/local/Cellar/pgcli/3.0.0/libexec/lib/python3.8/site-packages/pgspecial/dbcommands.py", line 302, in list_objects\n    cur.execute(sql)\n  File "/usr/local/Cellar/pgcli/3.0.0/libexec/lib/python3.8/site-packages/pgcli/pgexecute.py", line 39, in _wait_select\n    state = conn.poll()\npsycopg2.OperationalError: server closed the connection unexpectedly\n\tThis probably means the server terminated abnormally\n\tbefore or while processing the request.\n\n'
2020-09-11 23:11:40,486 (85612/MainThread) pgcli.main ERROR - sql: '\\d', error: OperationalError('server closed the connection unexpectedly\n\tThis probably means the server terminated abnormally\n\tbefore or while processing the request.\n')
2020-09-11 23:11:40,489 (85612/MainThread) pgcli.main ERROR - traceback: 'Traceback (most recent call last):\n  File "/usr/local/Cellar/pgcli/3.0.0/libexec/lib/python3.8/site-packages/pgcli/main.py", line 634, in execute_command\n    output, query = self._evaluate_command(text)\n  File "/usr/local/Cellar/pgcli/3.0.0/libexec/lib/python3.8/site-packages/pgcli/main.py", line 880, in _evaluate_command\n    for title, cur, headers, status, sql, success, is_special in res:\n  File "/usr/local/Cellar/pgcli/3.0.0/libexec/lib/python3.8/site-packages/pgcli/pgexecute.py", line 398, in run\n    for result in pgspecial.execute(cur, sql):\n  File "/usr/local/Cellar/pgcli/3.0.0/libexec/lib/python3.8/site-packages/pgspecial/main.py", line 90, in execute\n    return special_cmd.handler(cur=cur, pattern=pattern, verbose=verbose)\n  File "/usr/local/Cellar/pgcli/3.0.0/libexec/lib/python3.8/site-packages/pgspecial/dbcommands.py", line 684, in describe_table_details\n    return list_objects(cur, pattern, verbose, [\'r\', \'p\', \'v\', \'m\', \'S\', \'f\', \'\'])\n  File "/usr/local/Cellar/pgcli/3.0.0/libexec/lib/python3.8/site-packages/pgspecial/dbcommands.py", line 302, in list_objects\n    cur.execute(sql)\n  File "/usr/local/Cellar/pgcli/3.0.0/libexec/lib/python3.8/site-packages/pgcli/pgexecute.py", line 39, in _wait_select\n    state = conn.poll()\npsycopg2.OperationalError: server closed the connection unexpectedly\n\tThis probably means the server terminated abnormally\n\tbefore or while processing the request.\n\n'
2020-09-12 02:14:40,223 (67310/MainThread) pgcli.main INFO - Default pager found in PAGER environment variable: "less"
2020-09-12 02:14:40,223 (67310/MainThread) pgcli.main WARNING - import keyring failed: ModuleNotFoundError("No module named 'keyring'").
2020-09-12 02:30:24,824 (93337/MainThread) pgcli.main INFO - Default pager found in PAGER environment variable: "less"
2020-09-12 02:30:24,825 (93337/MainThread) pgcli.main WARNING - import keyring failed: ModuleNotFoundError("No module named 'keyring'").
2020-09-14 10:12:19,119 (68075/MainThread) pgcli.main INFO - Default pager found in PAGER environment variable: "less"
2020-09-14 10:12:19,120 (68075/MainThread) pgcli.main WARNING - import keyring failed: ModuleNotFoundError("No module named 'keyring'").
2020-09-14 10:33:26,836 (68075/MainThread) pgcli.pgexecute ERROR - sql: "select * from public.talent_profiles where id = '13623fa9-2a97-4c49-9144-aa0e64da715'", error: InvalidTextRepresentation('invalid input syntax for type uuid: "13623fa9-2a97-4c49-9144-aa0e64da715"\nLINE 1: select * from public.talent_profiles where id = \'13623fa9-2a...\n                                                        ^\n')
2020-09-14 10:33:26,844 (68075/MainThread) pgcli.pgexecute ERROR - traceback: 'Traceback (most recent call last):\n  File "/usr/local/Cellar/pgcli/3.0.0/libexec/lib/python3.8/site-packages/pgcli/pgexecute.py", line 409, in run\n    yield self.execute_normal_sql(sql) + (sql, True, False)\n  File "/usr/local/Cellar/pgcli/3.0.0/libexec/lib/python3.8/site-packages/pgcli/pgexecute.py", line 444, in execute_normal_sql\n    cur.execute(split_sql)\npsycopg2.errors.InvalidTextRepresentation: invalid input syntax for type uuid: "13623fa9-2a97-4c49-9144-aa0e64da715"\nLINE 1: select * from public.talent_profiles where id = \'13623fa9-2a...\n                                                        ^\n\n'
2020-09-14 10:33:33,185 (68075/MainThread) pgcli.pgexecute ERROR - sql: "select * from public.talent_profiles where id='13623fa9-2a97-4c49-9144-aa0e64da715'", error: InvalidTextRepresentation('invalid input syntax for type uuid: "13623fa9-2a97-4c49-9144-aa0e64da715"\nLINE 1: select * from public.talent_profiles where id=\'13623fa9-2a97...\n                                                      ^\n')
2020-09-14 10:33:33,186 (68075/MainThread) pgcli.pgexecute ERROR - traceback: 'Traceback (most recent call last):\n  File "/usr/local/Cellar/pgcli/3.0.0/libexec/lib/python3.8/site-packages/pgcli/pgexecute.py", line 409, in run\n    yield self.execute_normal_sql(sql) + (sql, True, False)\n  File "/usr/local/Cellar/pgcli/3.0.0/libexec/lib/python3.8/site-packages/pgcli/pgexecute.py", line 444, in execute_normal_sql\n    cur.execute(split_sql)\npsycopg2.errors.InvalidTextRepresentation: invalid input syntax for type uuid: "13623fa9-2a97-4c49-9144-aa0e64da715"\nLINE 1: select * from public.talent_profiles where id=\'13623fa9-2a97...\n                                                      ^\n\n'
2020-09-14 10:33:42,342 (68075/MainThread) pgcli.pgexecute ERROR - sql: 'select * from public.talent_profiles where id=13623fa9-2a97-4c49-9144-aa0e64da715', error: SyntaxError('syntax error at or near "fa9"\nLINE 1: ...elect * from public.talent_profiles where id=13623fa9-2a97-4...\n                                                             ^\n')
2020-09-14 10:33:42,342 (68075/MainThread) pgcli.pgexecute ERROR - traceback: 'Traceback (most recent call last):\n  File "/usr/local/Cellar/pgcli/3.0.0/libexec/lib/python3.8/site-packages/pgcli/pgexecute.py", line 409, in run\n    yield self.execute_normal_sql(sql) + (sql, True, False)\n  File "/usr/local/Cellar/pgcli/3.0.0/libexec/lib/python3.8/site-packages/pgcli/pgexecute.py", line 444, in execute_normal_sql\n    cur.execute(split_sql)\npsycopg2.errors.SyntaxError: syntax error at or near "fa9"\nLINE 1: ...elect * from public.talent_profiles where id=13623fa9-2a97-4...\n                                                             ^\n\n'
2020-09-14 10:33:53,051 (68075/MainThread) pgcli.pgexecute ERROR - sql: 'select * from public.talent_profiles where id=13623fa9-2a97-4c49-9144-aa0e64da715', error: SyntaxError('syntax error at or near "fa9"\nLINE 1: ...elect * from public.talent_profiles where id=13623fa9-2a97-4...\n                                                             ^\n')
2020-09-14 10:33:53,051 (68075/MainThread) pgcli.pgexecute ERROR - traceback: 'Traceback (most recent call last):\n  File "/usr/local/Cellar/pgcli/3.0.0/libexec/lib/python3.8/site-packages/pgcli/pgexecute.py", line 409, in run\n    yield self.execute_normal_sql(sql) + (sql, True, False)\n  File "/usr/local/Cellar/pgcli/3.0.0/libexec/lib/python3.8/site-packages/pgcli/pgexecute.py", line 444, in execute_normal_sql\n    cur.execute(split_sql)\npsycopg2.errors.SyntaxError: syntax error at or near "fa9"\nLINE 1: ...elect * from public.talent_profiles where id=13623fa9-2a97-4...\n                                                             ^\n\n'
2020-09-14 10:33:57,908 (68075/MainThread) pgcli.pgexecute ERROR - sql: 'select * from public.talent_profiles where id= 13623fa9-2a97-4c49-9144-aa0e64da715', error: SyntaxError('syntax error at or near "fa9"\nLINE 1: ...lect * from public.talent_profiles where id= 13623fa9-2a97-4...\n                                                             ^\n')
2020-09-14 10:33:57,909 (68075/MainThread) pgcli.pgexecute ERROR - traceback: 'Traceback (most recent call last):\n  File "/usr/local/Cellar/pgcli/3.0.0/libexec/lib/python3.8/site-packages/pgcli/pgexecute.py", line 409, in run\n    yield self.execute_normal_sql(sql) + (sql, True, False)\n  File "/usr/local/Cellar/pgcli/3.0.0/libexec/lib/python3.8/site-packages/pgcli/pgexecute.py", line 444, in execute_normal_sql\n    cur.execute(split_sql)\npsycopg2.errors.SyntaxError: syntax error at or near "fa9"\nLINE 1: ...lect * from public.talent_profiles where id= 13623fa9-2a97-4...\n                                                             ^\n\n'
2020-09-14 10:34:02,006 (68075/MainThread) pgcli.pgexecute ERROR - sql: 'select * from public.talent_profiles where id="13623fa9-2a97-4c49-9144-aa0e64da715', error: SyntaxError('unterminated quoted identifier at or near ""13623fa9-2a97-4c49-9144-aa0e64da715"\nLINE 1: select * from public.talent_profiles where id="13623fa9-2a97...\n                                                      ^\n')
2020-09-14 10:34:02,006 (68075/MainThread) pgcli.pgexecute ERROR - traceback: 'Traceback (most recent call last):\n  File "/usr/local/Cellar/pgcli/3.0.0/libexec/lib/python3.8/site-packages/pgcli/pgexecute.py", line 409, in run\n    yield self.execute_normal_sql(sql) + (sql, True, False)\n  File "/usr/local/Cellar/pgcli/3.0.0/libexec/lib/python3.8/site-packages/pgcli/pgexecute.py", line 444, in execute_normal_sql\n    cur.execute(split_sql)\npsycopg2.errors.SyntaxError: unterminated quoted identifier at or near ""13623fa9-2a97-4c49-9144-aa0e64da715"\nLINE 1: select * from public.talent_profiles where id="13623fa9-2a97...\n                                                      ^\n\n'
2020-09-14 10:34:04,573 (68075/MainThread) pgcli.pgexecute ERROR - sql: 'select * from public.talent_profiles where id="13623fa9-2a97-4c49-9144-aa0e64da715"', error: UndefinedColumn('column "13623fa9-2a97-4c49-9144-aa0e64da715" does not exist\nLINE 1: select * from public.talent_profiles where id="13623fa9-2a97...\n                                                      ^\n')
2020-09-14 10:34:04,574 (68075/MainThread) pgcli.pgexecute ERROR - traceback: 'Traceback (most recent call last):\n  File "/usr/local/Cellar/pgcli/3.0.0/libexec/lib/python3.8/site-packages/pgcli/pgexecute.py", line 409, in run\n    yield self.execute_normal_sql(sql) + (sql, True, False)\n  File "/usr/local/Cellar/pgcli/3.0.0/libexec/lib/python3.8/site-packages/pgcli/pgexecute.py", line 444, in execute_normal_sql\n    cur.execute(split_sql)\npsycopg2.errors.UndefinedColumn: column "13623fa9-2a97-4c49-9144-aa0e64da715" does not exist\nLINE 1: select * from public.talent_profiles where id="13623fa9-2a97...\n                                                      ^\n\n'
2020-09-14 10:34:15,989 (68075/MainThread) pgcli.pgexecute ERROR - sql: 'select * from public.talent_profiles where ID="13623fa9-2a97-4c49-9144-aa0e64da715"', error: UndefinedColumn('column "13623fa9-2a97-4c49-9144-aa0e64da715" does not exist\nLINE 1: select * from public.talent_profiles where ID="13623fa9-2a97...\n                                                      ^\n')
2020-09-14 10:34:15,989 (68075/MainThread) pgcli.pgexecute ERROR - traceback: 'Traceback (most recent call last):\n  File "/usr/local/Cellar/pgcli/3.0.0/libexec/lib/python3.8/site-packages/pgcli/pgexecute.py", line 409, in run\n    yield self.execute_normal_sql(sql) + (sql, True, False)\n  File "/usr/local/Cellar/pgcli/3.0.0/libexec/lib/python3.8/site-packages/pgcli/pgexecute.py", line 444, in execute_normal_sql\n    cur.execute(split_sql)\npsycopg2.errors.UndefinedColumn: column "13623fa9-2a97-4c49-9144-aa0e64da715" does not exist\nLINE 1: select * from public.talent_profiles where ID="13623fa9-2a97...\n                                                      ^\n\n'
2020-09-14 10:34:35,322 (68075/MainThread) pgcli.pgexecute ERROR - sql: 'select * from public.talent_profiles where ID="13623fa9-2a97-4c49-9144-aa0e64da7153"', error: UndefinedColumn('column "13623fa9-2a97-4c49-9144-aa0e64da7153" does not exist\nLINE 1: select * from public.talent_profiles where ID="13623fa9-2a97...\n                                                      ^\n')
2020-09-14 10:34:35,322 (68075/MainThread) pgcli.pgexecute ERROR - traceback: 'Traceback (most recent call last):\n  File "/usr/local/Cellar/pgcli/3.0.0/libexec/lib/python3.8/site-packages/pgcli/pgexecute.py", line 409, in run\n    yield self.execute_normal_sql(sql) + (sql, True, False)\n  File "/usr/local/Cellar/pgcli/3.0.0/libexec/lib/python3.8/site-packages/pgcli/pgexecute.py", line 444, in execute_normal_sql\n    cur.execute(split_sql)\npsycopg2.errors.UndefinedColumn: column "13623fa9-2a97-4c49-9144-aa0e64da7153" does not exist\nLINE 1: select * from public.talent_profiles where ID="13623fa9-2a97...\n                                                      ^\n\n'
2020-09-14 10:34:43,254 (68075/MainThread) pgcli.pgexecute ERROR - sql: 'select * from public.talent_profiles where id=13623fa9-2a97-4c49-9144-aa0e64da7153', error: SyntaxError('syntax error at or near "fa9"\nLINE 1: ...elect * from public.talent_profiles where id=13623fa9-2a97-4...\n                                                             ^\n')
2020-09-14 10:34:43,254 (68075/MainThread) pgcli.pgexecute ERROR - traceback: 'Traceback (most recent call last):\n  File "/usr/local/Cellar/pgcli/3.0.0/libexec/lib/python3.8/site-packages/pgcli/pgexecute.py", line 409, in run\n    yield self.execute_normal_sql(sql) + (sql, True, False)\n  File "/usr/local/Cellar/pgcli/3.0.0/libexec/lib/python3.8/site-packages/pgcli/pgexecute.py", line 444, in execute_normal_sql\n    cur.execute(split_sql)\npsycopg2.errors.SyntaxError: syntax error at or near "fa9"\nLINE 1: ...elect * from public.talent_profiles where id=13623fa9-2a97-4...\n                                                             ^\n\n'
2020-09-14 10:55:32,212 (68075/MainThread) pgcli.pgexecute ERROR - sql: "UPDATE public.talent_profiles SET status='inprogress' WHERE id='ec9d2dba-fbb7-47cf-8f59-6348d5e5c7cc'", error: InvalidTextRepresentation('invalid input value for enum talent_profiles_status_enum: "inprogress"\nLINE 1: UPDATE public.talent_profiles SET status=\'inprogress\' WHERE ...\n                                                 ^\n')
2020-09-14 10:55:32,219 (68075/MainThread) pgcli.pgexecute ERROR - traceback: 'Traceback (most recent call last):\n  File "/usr/local/Cellar/pgcli/3.0.0/libexec/lib/python3.8/site-packages/pgcli/pgexecute.py", line 409, in run\n    yield self.execute_normal_sql(sql) + (sql, True, False)\n  File "/usr/local/Cellar/pgcli/3.0.0/libexec/lib/python3.8/site-packages/pgcli/pgexecute.py", line 444, in execute_normal_sql\n    cur.execute(split_sql)\npsycopg2.errors.InvalidTextRepresentation: invalid input value for enum talent_profiles_status_enum: "inprogress"\nLINE 1: UPDATE public.talent_profiles SET status=\'inprogress\' WHERE ...\n                                                 ^\n\n'
2020-09-14 10:55:50,027 (68075/MainThread) pgcli.pgexecute ERROR - sql: "UPDATE public.talent_profiles SET status='inprogress' WHERE id='ec9d2dba-fbb7-47cf-8f59-6348d5e5c7cc'", error: InvalidTextRepresentation('invalid input value for enum talent_profiles_status_enum: "inprogress"\nLINE 1: UPDATE public.talent_profiles SET status=\'inprogress\' WHERE ...\n                                                 ^\n')
2020-09-14 10:55:50,027 (68075/MainThread) pgcli.pgexecute ERROR - traceback: 'Traceback (most recent call last):\n  File "/usr/local/Cellar/pgcli/3.0.0/libexec/lib/python3.8/site-packages/pgcli/pgexecute.py", line 409, in run\n    yield self.execute_normal_sql(sql) + (sql, True, False)\n  File "/usr/local/Cellar/pgcli/3.0.0/libexec/lib/python3.8/site-packages/pgcli/pgexecute.py", line 444, in execute_normal_sql\n    cur.execute(split_sql)\npsycopg2.errors.InvalidTextRepresentation: invalid input value for enum talent_profiles_status_enum: "inprogress"\nLINE 1: UPDATE public.talent_profiles SET status=\'inprogress\' WHERE ...\n                                                 ^\n\n'
2020-09-14 11:11:32,583 (29244/MainThread) pgcli.main INFO - Default pager found in PAGER environment variable: "less"
2020-09-14 11:11:32,584 (29244/MainThread) pgcli.main WARNING - import keyring failed: ModuleNotFoundError("No module named 'keyring'").
2020-09-14 12:32:24,698 (68075/MainThread) pgcli.pgexecute ERROR - sql: 'UPDATE public.users', error: SyntaxError('syntax error at end of input\nLINE 1: UPDATE public.users\n                           ^\n')
2020-09-14 12:32:24,707 (68075/MainThread) pgcli.pgexecute ERROR - traceback: 'Traceback (most recent call last):\n  File "/usr/local/Cellar/pgcli/3.0.0/libexec/lib/python3.8/site-packages/pgcli/pgexecute.py", line 409, in run\n    yield self.execute_normal_sql(sql) + (sql, True, False)\n  File "/usr/local/Cellar/pgcli/3.0.0/libexec/lib/python3.8/site-packages/pgcli/pgexecute.py", line 444, in execute_normal_sql\n    cur.execute(split_sql)\npsycopg2.errors.SyntaxError: syntax error at end of input\nLINE 1: UPDATE public.users\n                           ^\n\n'
2020-09-14 12:32:28,067 (68075/MainThread) pgcli.pgexecute ERROR - sql: 'UPDATE public.users', error: SyntaxError('syntax error at end of input\nLINE 1: UPDATE public.users\n                           ^\n')
2020-09-14 12:32:28,068 (68075/MainThread) pgcli.pgexecute ERROR - traceback: 'Traceback (most recent call last):\n  File "/usr/local/Cellar/pgcli/3.0.0/libexec/lib/python3.8/site-packages/pgcli/pgexecute.py", line 409, in run\n    yield self.execute_normal_sql(sql) + (sql, True, False)\n  File "/usr/local/Cellar/pgcli/3.0.0/libexec/lib/python3.8/site-packages/pgcli/pgexecute.py", line 444, in execute_normal_sql\n    cur.execute(split_sql)\npsycopg2.errors.SyntaxError: syntax error at end of input\nLINE 1: UPDATE public.users\n                           ^\n\n'
2020-09-14 12:32:46,080 (68075/MainThread) pgcli.pgexecute ERROR - sql: "UPDATE public.users\n SET talent_code=aaaaa WHERE email='ild+louis3@nucleusstudio.io'", error: UndefinedColumn('column "aaaaa" does not exist\nLINE 2:  SET talent_code=aaaaa WHERE email=\'ild+louis3@nucleusstudio...\n                         ^\n')
2020-09-14 12:32:46,086 (68075/MainThread) pgcli.pgexecute ERROR - traceback: 'Traceback (most recent call last):\n  File "/usr/local/Cellar/pgcli/3.0.0/libexec/lib/python3.8/site-packages/pgcli/pgexecute.py", line 409, in run\n    yield self.execute_normal_sql(sql) + (sql, True, False)\n  File "/usr/local/Cellar/pgcli/3.0.0/libexec/lib/python3.8/site-packages/pgcli/pgexecute.py", line 444, in execute_normal_sql\n    cur.execute(split_sql)\npsycopg2.errors.UndefinedColumn: column "aaaaa" does not exist\nLINE 2:  SET talent_code=aaaaa WHERE email=\'ild+louis3@nucleusstudio...\n                         ^\n\n'
2020-09-14 14:12:10,658 (68075/MainThread) pgcli.pgexecute ERROR - sql: "UPDATE public.users\nSET talent_profile_id=ec9d2dba-fbb7-47cf-8f59-6348\n d5e5c7cc\nWHERE email='ild+louis3@nucleusstudio.io'", error: SyntaxError('syntax error at or near "cf"\nLINE 2: SET talent_profile_id=ec9d2dba-fbb7-47cf-8f59-6348\n                                              ^\n')
2020-09-14 14:12:10,660 (68075/MainThread) pgcli.pgexecute ERROR - traceback: 'Traceback (most recent call last):\n  File "/usr/local/Cellar/pgcli/3.0.0/libexec/lib/python3.8/site-packages/pgcli/pgexecute.py", line 409, in run\n    yield self.execute_normal_sql(sql) + (sql, True, False)\n  File "/usr/local/Cellar/pgcli/3.0.0/libexec/lib/python3.8/site-packages/pgcli/pgexecute.py", line 444, in execute_normal_sql\n    cur.execute(split_sql)\npsycopg2.errors.SyntaxError: syntax error at or near "cf"\nLINE 2: SET talent_profile_id=ec9d2dba-fbb7-47cf-8f59-6348\n                                              ^\n\n'
2020-09-15 14:37:19,722 (29244/MainThread) pgcli.pgexecute ERROR - sql: "UPDATE public.users\n SET talent_profile_id=null WHERE email='ild+user@nucleusstudio.io'", error: OperationalError('SSL SYSCALL error: Operation timed out\n')
2020-09-15 14:37:19,728 (29244/MainThread) pgcli.pgexecute ERROR - traceback: 'Traceback (most recent call last):\n  File "/usr/local/Cellar/pgcli/3.0.0/libexec/lib/python3.8/site-packages/pgcli/pgexecute.py", line 409, in run\n    yield self.execute_normal_sql(sql) + (sql, True, False)\n  File "/usr/local/Cellar/pgcli/3.0.0/libexec/lib/python3.8/site-packages/pgcli/pgexecute.py", line 444, in execute_normal_sql\n    cur.execute(split_sql)\npsycopg2.OperationalError: SSL SYSCALL error: Operation timed out\n\n'
2020-09-15 14:37:24,104 (29244/MainThread) pgcli.pgexecute ERROR - sql: "UPDATE public.users\n SET talent_profile_id=null WHERE email='ild+user@nucleusstudio.io'", error: OperationalError('SSL SYSCALL error: EOF detected\n')
2020-09-15 14:37:24,104 (29244/MainThread) pgcli.pgexecute ERROR - traceback: 'Traceback (most recent call last):\n  File "/usr/local/Cellar/pgcli/3.0.0/libexec/lib/python3.8/site-packages/pgcli/pgexecute.py", line 409, in run\n    yield self.execute_normal_sql(sql) + (sql, True, False)\n  File "/usr/local/Cellar/pgcli/3.0.0/libexec/lib/python3.8/site-packages/pgcli/pgexecute.py", line 444, in execute_normal_sql\n    cur.execute(split_sql)\npsycopg2.OperationalError: SSL SYSCALL error: EOF detected\n\n'
2020-09-15 14:37:24,104 (29244/MainThread) pgcli.main ERROR - sql: " UPDATE public.users\n SET talent_profile_id=null WHERE email='ild+user@nucleusstudio.io'", error: OperationalError('SSL SYSCALL error: EOF detected\n')
2020-09-15 14:37:24,106 (29244/MainThread) pgcli.main ERROR - traceback: 'Traceback (most recent call last):\n  File "/usr/local/Cellar/pgcli/3.0.0/libexec/lib/python3.8/site-packages/pgcli/main.py", line 634, in execute_command\n    output, query = self._evaluate_command(text)\n  File "/usr/local/Cellar/pgcli/3.0.0/libexec/lib/python3.8/site-packages/pgcli/main.py", line 880, in _evaluate_command\n    for title, cur, headers, status, sql, success, is_special in res:\n  File "/usr/local/Cellar/pgcli/3.0.0/libexec/lib/python3.8/site-packages/pgcli/pgexecute.py", line 409, in run\n    yield self.execute_normal_sql(sql) + (sql, True, False)\n  File "/usr/local/Cellar/pgcli/3.0.0/libexec/lib/python3.8/site-packages/pgcli/pgexecute.py", line 444, in execute_normal_sql\n    cur.execute(split_sql)\npsycopg2.OperationalError: SSL SYSCALL error: EOF detected\n\n'
2020-09-15 17:33:34,808 (68075/MainThread) pgcli.pgexecute ERROR - sql: "UPDATE public.talent_profiles SET status='new' WHERE id='ec9d2dba-fbb7-47cf-8f59-6348d5e5c7cc'", error: OperationalError('SSL SYSCALL error: Operation timed out\n')
2020-09-15 17:33:34,811 (68075/MainThread) pgcli.pgexecute ERROR - traceback: 'Traceback (most recent call last):\n  File "/usr/local/Cellar/pgcli/3.0.0/libexec/lib/python3.8/site-packages/pgcli/pgexecute.py", line 409, in run\n    yield self.execute_normal_sql(sql) + (sql, True, False)\n  File "/usr/local/Cellar/pgcli/3.0.0/libexec/lib/python3.8/site-packages/pgcli/pgexecute.py", line 444, in execute_normal_sql\n    cur.execute(split_sql)\npsycopg2.OperationalError: SSL SYSCALL error: Operation timed out\n\n'
2020-09-15 17:33:37,106 (68075/MainThread) pgcli.pgexecute ERROR - sql: "UPDATE public.talent_profiles SET status='new' WHERE id='ec9d2dba-fbb7-47cf-8f59-6348d5e5c7cc'", error: OperationalError('SSL SYSCALL error: EOF detected\n')
2020-09-15 17:33:37,107 (68075/MainThread) pgcli.pgexecute ERROR - traceback: 'Traceback (most recent call last):\n  File "/usr/local/Cellar/pgcli/3.0.0/libexec/lib/python3.8/site-packages/pgcli/pgexecute.py", line 409, in run\n    yield self.execute_normal_sql(sql) + (sql, True, False)\n  File "/usr/local/Cellar/pgcli/3.0.0/libexec/lib/python3.8/site-packages/pgcli/pgexecute.py", line 444, in execute_normal_sql\n    cur.execute(split_sql)\npsycopg2.OperationalError: SSL SYSCALL error: EOF detected\n\n'
2020-09-15 17:33:37,107 (68075/MainThread) pgcli.main ERROR - sql: "UPDATE public.talent_profiles SET status='new' WHERE id='ec9d2dba-fbb7-47cf-8f59-6348d5e5c7cc'", error: OperationalError('SSL SYSCALL error: EOF detected\n')
2020-09-15 17:33:37,108 (68075/MainThread) pgcli.main ERROR - traceback: 'Traceback (most recent call last):\n  File "/usr/local/Cellar/pgcli/3.0.0/libexec/lib/python3.8/site-packages/pgcli/main.py", line 634, in execute_command\n    output, query = self._evaluate_command(text)\n  File "/usr/local/Cellar/pgcli/3.0.0/libexec/lib/python3.8/site-packages/pgcli/main.py", line 880, in _evaluate_command\n    for title, cur, headers, status, sql, success, is_special in res:\n  File "/usr/local/Cellar/pgcli/3.0.0/libexec/lib/python3.8/site-packages/pgcli/pgexecute.py", line 409, in run\n    yield self.execute_normal_sql(sql) + (sql, True, False)\n  File "/usr/local/Cellar/pgcli/3.0.0/libexec/lib/python3.8/site-packages/pgcli/pgexecute.py", line 444, in execute_normal_sql\n    cur.execute(split_sql)\npsycopg2.OperationalError: SSL SYSCALL error: EOF detected\n\n'
2020-09-16 15:24:01,427 (26532/MainThread) pgcli.main INFO - Default pager found in PAGER environment variable: "less"
2020-09-16 15:24:01,428 (26532/MainThread) pgcli.main WARNING - import keyring failed: ModuleNotFoundError("No module named 'keyring'").
2020-09-16 15:26:10,706 (26532/MainThread) pgcli.pgexecute ERROR - sql: "UPDATE public.talent_profiles SET status='null' WHERE id='f143dd75-f817-4dbf-ac2b-d68c596c8691'", error: InvalidTextRepresentation('invalid input value for enum talent_profiles_status_enum: "null"\nLINE 1: UPDATE public.talent_profiles SET status=\'null\' WHERE id=\'f1...\n                                                 ^\n')
2020-09-16 15:26:10,713 (26532/MainThread) pgcli.pgexecute ERROR - traceback: 'Traceback (most recent call last):\n  File "/usr/local/Cellar/pgcli/3.0.0/libexec/lib/python3.8/site-packages/pgcli/pgexecute.py", line 409, in run\n    yield self.execute_normal_sql(sql) + (sql, True, False)\n  File "/usr/local/Cellar/pgcli/3.0.0/libexec/lib/python3.8/site-packages/pgcli/pgexecute.py", line 444, in execute_normal_sql\n    cur.execute(split_sql)\npsycopg2.errors.InvalidTextRepresentation: invalid input value for enum talent_profiles_status_enum: "null"\nLINE 1: UPDATE public.talent_profiles SET status=\'null\' WHERE id=\'f1...\n                                                 ^\n\n'
2020-09-16 15:27:26,758 (26532/MainThread) pgcli.pgexecute ERROR - sql: "UPDATE public.talent_profiles SET status=null WHERE id='f143dd75-f817-4dbf-ac2b-d68c596c8691'", error: OperationalError('PQcancel() -- connect() failed: Network is unreachable\n')
2020-09-16 15:27:26,764 (26532/MainThread) pgcli.pgexecute ERROR - traceback: 'Traceback (most recent call last):\n  File "/usr/local/Cellar/pgcli/3.0.0/libexec/lib/python3.8/site-packages/pgcli/pgexecute.py", line 43, in _wait_select\n    select.select([conn.fileno()], [], [], _WAIT_SELECT_TIMEOUT)\nKeyboardInterrupt\n\nDuring handling of the above exception, another exception occurred:\n\nTraceback (most recent call last):\n  File "/usr/local/Cellar/pgcli/3.0.0/libexec/lib/python3.8/site-packages/pgcli/pgexecute.py", line 409, in run\n    yield self.execute_normal_sql(sql) + (sql, True, False)\n  File "/usr/local/Cellar/pgcli/3.0.0/libexec/lib/python3.8/site-packages/pgcli/pgexecute.py", line 444, in execute_normal_sql\n    cur.execute(split_sql)\n  File "/usr/local/Cellar/pgcli/3.0.0/libexec/lib/python3.8/site-packages/pgcli/pgexecute.py", line 49, in _wait_select\n    conn.cancel()\npsycopg2.OperationalError: PQcancel() -- connect() failed: Network is unreachable\n\n'
2020-09-16 15:27:26,764 (26532/MainThread) pgcli.main ERROR - sql: "UPDATE public.talent_profiles SET status=null WHERE id='f143dd75-f817-4dbf-ac2b-d68c596c8691'", error: OperationalError('PQcancel() -- connect() failed: Network is unreachable\n')
2020-09-16 15:27:26,765 (26532/MainThread) pgcli.main ERROR - traceback: 'Traceback (most recent call last):\n  File "/usr/local/Cellar/pgcli/3.0.0/libexec/lib/python3.8/site-packages/pgcli/pgexecute.py", line 43, in _wait_select\n    select.select([conn.fileno()], [], [], _WAIT_SELECT_TIMEOUT)\nKeyboardInterrupt\n\nDuring handling of the above exception, another exception occurred:\n\nTraceback (most recent call last):\n  File "/usr/local/Cellar/pgcli/3.0.0/libexec/lib/python3.8/site-packages/pgcli/main.py", line 634, in execute_command\n    output, query = self._evaluate_command(text)\n  File "/usr/local/Cellar/pgcli/3.0.0/libexec/lib/python3.8/site-packages/pgcli/main.py", line 880, in _evaluate_command\n    for title, cur, headers, status, sql, success, is_special in res:\n  File "/usr/local/Cellar/pgcli/3.0.0/libexec/lib/python3.8/site-packages/pgcli/pgexecute.py", line 409, in run\n    yield self.execute_normal_sql(sql) + (sql, True, False)\n  File "/usr/local/Cellar/pgcli/3.0.0/libexec/lib/python3.8/site-packages/pgcli/pgexecute.py", line 444, in execute_normal_sql\n    cur.execute(split_sql)\n  File "/usr/local/Cellar/pgcli/3.0.0/libexec/lib/python3.8/site-packages/pgcli/pgexecute.py", line 49, in _wait_select\n    conn.cancel()\npsycopg2.OperationalError: PQcancel() -- connect() failed: Network is unreachable\n\n'
2020-09-16 15:27:29,228 (26532/MainThread) pgcli.main ERROR - sql: "UPDATE public.talent_profiles SET status=null WHERE id='f143dd75-f817-4dbf-ac2b-d68c596c8691'", error: InterfaceError('connection already closed')
2020-09-16 15:27:29,229 (26532/MainThread) pgcli.main ERROR - traceback: 'Traceback (most recent call last):\n  File "/usr/local/Cellar/pgcli/3.0.0/libexec/lib/python3.8/site-packages/pgcli/main.py", line 634, in execute_command\n    output, query = self._evaluate_command(text)\n  File "/usr/local/Cellar/pgcli/3.0.0/libexec/lib/python3.8/site-packages/pgcli/main.py", line 880, in _evaluate_command\n    for title, cur, headers, status, sql, success, is_special in res:\n  File "/usr/local/Cellar/pgcli/3.0.0/libexec/lib/python3.8/site-packages/pgcli/pgexecute.py", line 409, in run\n    yield self.execute_normal_sql(sql) + (sql, True, False)\n  File "/usr/local/Cellar/pgcli/3.0.0/libexec/lib/python3.8/site-packages/pgcli/pgexecute.py", line 443, in execute_normal_sql\n    cur = self.conn.cursor()\npsycopg2.InterfaceError: connection already closed\n'
2020-09-16 15:27:31,955 (26532/MainThread) pgcli.main ERROR - sql: "UPDATE public.talent_profiles SET status=null WHERE id='f143dd75-f817-4dbf-ac2b-d68c596c8691'", error: InterfaceError('connection already closed')
2020-09-16 15:27:31,956 (26532/MainThread) pgcli.main ERROR - traceback: 'Traceback (most recent call last):\n  File "/usr/local/Cellar/pgcli/3.0.0/libexec/lib/python3.8/site-packages/pgcli/main.py", line 634, in execute_command\n    output, query = self._evaluate_command(text)\n  File "/usr/local/Cellar/pgcli/3.0.0/libexec/lib/python3.8/site-packages/pgcli/main.py", line 880, in _evaluate_command\n    for title, cur, headers, status, sql, success, is_special in res:\n  File "/usr/local/Cellar/pgcli/3.0.0/libexec/lib/python3.8/site-packages/pgcli/pgexecute.py", line 409, in run\n    yield self.execute_normal_sql(sql) + (sql, True, False)\n  File "/usr/local/Cellar/pgcli/3.0.0/libexec/lib/python3.8/site-packages/pgcli/pgexecute.py", line 443, in execute_normal_sql\n    cur = self.conn.cursor()\npsycopg2.InterfaceError: connection already closed\n'
2020-09-16 15:27:35,582 (31125/MainThread) pgcli.main INFO - Default pager found in PAGER environment variable: "less"
2020-09-16 15:27:35,583 (31125/MainThread) pgcli.main WARNING - import keyring failed: ModuleNotFoundError("No module named 'keyring'").
2020-09-16 15:27:35,589 (31125/MainThread) pgcli.main ERROR - traceback: 'Traceback (most recent call last):\n  File "/usr/local/Cellar/pgcli/3.0.0/libexec/lib/python3.8/site-packages/pgcli/main.py", line 562, in connect\n    raise e\n  File "/usr/local/Cellar/pgcli/3.0.0/libexec/lib/python3.8/site-packages/pgcli/main.py", line 549, in connect\n    pgexecute = PGExecute(database, user, passwd, host, port, dsn, **kwargs)\n  File "/usr/local/Cellar/pgcli/3.0.0/libexec/lib/python3.8/site-packages/pgcli/pgexecute.py", line 214, in __init__\n    self.connect(database, user, password, host, port, dsn, **kwargs)\n  File "/usr/local/Cellar/pgcli/3.0.0/libexec/lib/python3.8/site-packages/pgcli/pgexecute.py", line 254, in connect\n    conn = psycopg2.connect(**conn_params)\n  File "/usr/local/Cellar/pgcli/3.0.0/libexec/lib/python3.8/site-packages/psycopg2/__init__.py", line 127, in connect\n    conn = _connect(dsn, connection_factory=connection_factory, **kwasync)\npsycopg2.OperationalError: could not translate host name "komi-staging.caswrr3mvv8s.us-east-1.rds.amazonaws.com" to address: nodename nor servname provided, or not known\n\n'
2020-09-16 15:28:52,320 (33049/MainThread) pgcli.main INFO - Default pager found in PAGER environment variable: "less"
2020-09-16 15:28:52,321 (33049/MainThread) pgcli.main WARNING - import keyring failed: ModuleNotFoundError("No module named 'keyring'").
2020-09-16 15:29:22,335 (33049/MainThread) pgcli.main ERROR - traceback: 'Traceback (most recent call last):\n  File "/usr/local/Cellar/pgcli/3.0.0/libexec/lib/python3.8/site-packages/pgcli/main.py", line 562, in connect\n    raise e\n  File "/usr/local/Cellar/pgcli/3.0.0/libexec/lib/python3.8/site-packages/pgcli/main.py", line 549, in connect\n    pgexecute = PGExecute(database, user, passwd, host, port, dsn, **kwargs)\n  File "/usr/local/Cellar/pgcli/3.0.0/libexec/lib/python3.8/site-packages/pgcli/pgexecute.py", line 214, in __init__\n    self.connect(database, user, password, host, port, dsn, **kwargs)\n  File "/usr/local/Cellar/pgcli/3.0.0/libexec/lib/python3.8/site-packages/pgcli/pgexecute.py", line 254, in connect\n    conn = psycopg2.connect(**conn_params)\n  File "/usr/local/Cellar/pgcli/3.0.0/libexec/lib/python3.8/site-packages/psycopg2/__init__.py", line 127, in connect\n    conn = _connect(dsn, connection_factory=connection_factory, **kwasync)\npsycopg2.OperationalError: could not translate host name "komi-staging.caswrr3mvv8s.us-east-1.rds.amazonaws.com" to address: nodename nor servname provided, or not known\n\n'
2020-09-16 15:29:36,732 (33975/MainThread) pgcli.main INFO - Default pager found in PAGER environment variable: "less"
2020-09-16 15:29:36,733 (33975/MainThread) pgcli.main WARNING - import keyring failed: ModuleNotFoundError("No module named 'keyring'").
2020-09-16 15:30:06,747 (33975/MainThread) pgcli.main ERROR - traceback: 'Traceback (most recent call last):\n  File "/usr/local/Cellar/pgcli/3.0.0/libexec/lib/python3.8/site-packages/pgcli/main.py", line 562, in connect\n    raise e\n  File "/usr/local/Cellar/pgcli/3.0.0/libexec/lib/python3.8/site-packages/pgcli/main.py", line 549, in connect\n    pgexecute = PGExecute(database, user, passwd, host, port, dsn, **kwargs)\n  File "/usr/local/Cellar/pgcli/3.0.0/libexec/lib/python3.8/site-packages/pgcli/pgexecute.py", line 214, in __init__\n    self.connect(database, user, password, host, port, dsn, **kwargs)\n  File "/usr/local/Cellar/pgcli/3.0.0/libexec/lib/python3.8/site-packages/pgcli/pgexecute.py", line 254, in connect\n    conn = psycopg2.connect(**conn_params)\n  File "/usr/local/Cellar/pgcli/3.0.0/libexec/lib/python3.8/site-packages/psycopg2/__init__.py", line 127, in connect\n    conn = _connect(dsn, connection_factory=connection_factory, **kwasync)\npsycopg2.OperationalError: could not translate host name "komi-staging.caswrr3mvv8s.us-east-1.rds.amazonaws.com" to address: nodename nor servname provided, or not known\n\n'
2020-09-16 15:30:09,738 (34623/MainThread) pgcli.main INFO - Default pager found in PAGER environment variable: "less"
2020-09-16 15:30:09,739 (34623/MainThread) pgcli.main WARNING - import keyring failed: ModuleNotFoundError("No module named 'keyring'").
2020-09-16 15:32:17,419 (34623/MainThread) pgcli.pgexecute ERROR - sql: "UPDATE public.talent_profiles SET status=null  WHERE id='f143dd75-f817-4dbf-ac2b-d68c596c8691'", error: NotNullViolation('null value in column "status" violates not-null constraint\nDETAIL:  Failing row contains (2020-09-16 04:43:16.728227+00, 2020-09-16 04:43:29.933155+00, f143dd75-f817-4dbf-ac2b-d68c596c8691, Ashley, Roberts, {https://s3.amazonaws.com/uifaces/faces/twitter/grahamkennery/12..., https://www.instagram.com/ild, null, 0, app, null, null, 303-757-2400, https://komi-assets.s3.amazonaws.com/talents/Music/Ashley+Robert..., Necessitatibus laboriosam nostrum ut non. Ut possimus quo et dol..., null).\n')
2020-09-16 15:32:17,427 (34623/MainThread) pgcli.pgexecute ERROR - traceback: 'Traceback (most recent call last):\n  File "/usr/local/Cellar/pgcli/3.0.0/libexec/lib/python3.8/site-packages/pgcli/pgexecute.py", line 409, in run\n    yield self.execute_normal_sql(sql) + (sql, True, False)\n  File "/usr/local/Cellar/pgcli/3.0.0/libexec/lib/python3.8/site-packages/pgcli/pgexecute.py", line 444, in execute_normal_sql\n    cur.execute(split_sql)\npsycopg2.errors.NotNullViolation: null value in column "status" violates not-null constraint\nDETAIL:  Failing row contains (2020-09-16 04:43:16.728227+00, 2020-09-16 04:43:29.933155+00, f143dd75-f817-4dbf-ac2b-d68c596c8691, Ashley, Roberts, {https://s3.amazonaws.com/uifaces/faces/twitter/grahamkennery/12..., https://www.instagram.com/ild, null, 0, app, null, null, 303-757-2400, https://komi-assets.s3.amazonaws.com/talents/Music/Ashley+Robert..., Necessitatibus laboriosam nostrum ut non. Ut possimus quo et dol..., null).\n\n'
2020-09-16 15:32:20,798 (34623/MainThread) pgcli.pgexecute ERROR - sql: "UPDATE public.talent_profiles SET status=null  WHERE id='f143dd75-f817-4dbf-ac2b-d68c596c8691'", error: NotNullViolation('null value in column "status" violates not-null constraint\nDETAIL:  Failing row contains (2020-09-16 04:43:16.728227+00, 2020-09-16 04:43:29.933155+00, f143dd75-f817-4dbf-ac2b-d68c596c8691, Ashley, Roberts, {https://s3.amazonaws.com/uifaces/faces/twitter/grahamkennery/12..., https://www.instagram.com/ild, null, 0, app, null, null, 303-757-2400, https://komi-assets.s3.amazonaws.com/talents/Music/Ashley+Robert..., Necessitatibus laboriosam nostrum ut non. Ut possimus quo et dol..., null).\n')
2020-09-16 15:32:20,799 (34623/MainThread) pgcli.pgexecute ERROR - traceback: 'Traceback (most recent call last):\n  File "/usr/local/Cellar/pgcli/3.0.0/libexec/lib/python3.8/site-packages/pgcli/pgexecute.py", line 409, in run\n    yield self.execute_normal_sql(sql) + (sql, True, False)\n  File "/usr/local/Cellar/pgcli/3.0.0/libexec/lib/python3.8/site-packages/pgcli/pgexecute.py", line 444, in execute_normal_sql\n    cur.execute(split_sql)\npsycopg2.errors.NotNullViolation: null value in column "status" violates not-null constraint\nDETAIL:  Failing row contains (2020-09-16 04:43:16.728227+00, 2020-09-16 04:43:29.933155+00, f143dd75-f817-4dbf-ac2b-d68c596c8691, Ashley, Roberts, {https://s3.amazonaws.com/uifaces/faces/twitter/grahamkennery/12..., https://www.instagram.com/ild, null, 0, app, null, null, 303-757-2400, https://komi-assets.s3.amazonaws.com/talents/Music/Ashley+Robert..., Necessitatibus laboriosam nostrum ut non. Ut possimus quo et dol..., null).\n\n'
2020-09-16 17:12:19,518 (67240/MainThread) pgcli.main INFO - Default pager found in PAGER environment variable: "less"
2020-09-16 17:12:19,519 (67240/MainThread) pgcli.main WARNING - import keyring failed: ModuleNotFoundError("No module named 'keyring'").
2020-09-16 17:16:19,256 (67240/MainThread) pgcli.pgexecute ERROR - sql: "UPDATE public.users\n  SET talent_profile_id=f143dd75-f817-4dbf-ac2b-d68c596c8691 WHERE email='ild+talent@nucleusstudio.io'", error: SyntaxError('syntax error at or near "dbf"\nLINE 2:   SET talent_profile_id=f143dd75-f817-4dbf-ac2b-d68c596c8691...\n                                               ^\n')
2020-09-16 17:16:19,264 (67240/MainThread) pgcli.pgexecute ERROR - traceback: 'Traceback (most recent call last):\n  File "/usr/local/Cellar/pgcli/3.0.0/libexec/lib/python3.8/site-packages/pgcli/pgexecute.py", line 409, in run\n    yield self.execute_normal_sql(sql) + (sql, True, False)\n  File "/usr/local/Cellar/pgcli/3.0.0/libexec/lib/python3.8/site-packages/pgcli/pgexecute.py", line 444, in execute_normal_sql\n    cur.execute(split_sql)\npsycopg2.errors.SyntaxError: syntax error at or near "dbf"\nLINE 2:   SET talent_profile_id=f143dd75-f817-4dbf-ac2b-d68c596c8691...\n                                               ^\n\n'
2020-09-17 12:07:07,417 (51610/MainThread) pgcli.main INFO - Default pager found in PAGER environment variable: "less"
2020-09-17 12:07:07,418 (51610/MainThread) pgcli.main WARNING - import keyring failed: ModuleNotFoundError("No module named 'keyring'").
2020-09-17 16:38:52,091 (51610/MainThread) pgcli.pgexecute ERROR - sql: "UPDATE public.users\n  SET active_code='aaaaa'  WHERE email='ild+user@nucleusstudio.io'", error: UndefinedColumn('column "active_code" of relation "users" does not exist\nLINE 2:   SET active_code=\'aaaaa\'  WHERE email=\'ild+user@nucleusstud...\n              ^\n')
2020-09-17 16:38:52,095 (51610/MainThread) pgcli.pgexecute ERROR - traceback: 'Traceback (most recent call last):\n  File "/usr/local/Cellar/pgcli/3.0.0/libexec/lib/python3.8/site-packages/pgcli/pgexecute.py", line 409, in run\n    yield self.execute_normal_sql(sql) + (sql, True, False)\n  File "/usr/local/Cellar/pgcli/3.0.0/libexec/lib/python3.8/site-packages/pgcli/pgexecute.py", line 444, in execute_normal_sql\n    cur.execute(split_sql)\npsycopg2.errors.UndefinedColumn: column "active_code" of relation "users" does not exist\nLINE 2:   SET active_code=\'aaaaa\'  WHERE email=\'ild+user@nucleusstud...\n              ^\n\n'
2020-09-17 16:39:10,493 (51610/MainThread) pgcli.pgexecute ERROR - sql: "UPDATE public.users\n  SET activeCode='aaaaa'  WHERE email='ild+user@nucleusstudio.io'", error: UndefinedColumn('column "activecode" of relation "users" does not exist\nLINE 2:   SET activeCode=\'aaaaa\'  WHERE email=\'ild+user@nucleusstudi...\n              ^\n')
2020-09-17 16:39:10,499 (51610/MainThread) pgcli.pgexecute ERROR - traceback: 'Traceback (most recent call last):\n  File "/usr/local/Cellar/pgcli/3.0.0/libexec/lib/python3.8/site-packages/pgcli/pgexecute.py", line 409, in run\n    yield self.execute_normal_sql(sql) + (sql, True, False)\n  File "/usr/local/Cellar/pgcli/3.0.0/libexec/lib/python3.8/site-packages/pgcli/pgexecute.py", line 444, in execute_normal_sql\n    cur.execute(split_sql)\npsycopg2.errors.UndefinedColumn: column "activecode" of relation "users" does not exist\nLINE 2:   SET activeCode=\'aaaaa\'  WHERE email=\'ild+user@nucleusstudi...\n              ^\n\n'
2020-09-17 16:39:44,095 (51610/MainThread) pgcli.pgexecute ERROR - sql: "UPDATE public.users\n SET talent_code='1aaaa' WHERE email='ild+user@nucleusstudio.io'", error: UndefinedColumn('column "talent_code" of relation "users" does not exist\nLINE 2:  SET talent_code=\'1aaaa\' WHERE email=\'ild+user@nucleusstudio...\n             ^\n')
2020-09-17 16:39:44,101 (51610/MainThread) pgcli.pgexecute ERROR - traceback: 'Traceback (most recent call last):\n  File "/usr/local/Cellar/pgcli/3.0.0/libexec/lib/python3.8/site-packages/pgcli/pgexecute.py", line 409, in run\n    yield self.execute_normal_sql(sql) + (sql, True, False)\n  File "/usr/local/Cellar/pgcli/3.0.0/libexec/lib/python3.8/site-packages/pgcli/pgexecute.py", line 444, in execute_normal_sql\n    cur.execute(split_sql)\npsycopg2.errors.UndefinedColumn: column "talent_code" of relation "users" does not exist\nLINE 2:  SET talent_code=\'1aaaa\' WHERE email=\'ild+user@nucleusstudio...\n             ^\n\n'
2020-09-17 16:39:56,138 (51610/MainThread) pgcli.pgexecute ERROR - sql: "UPDATE public.users\n SET talent_code='1aaaa' WHERE email='ild+user@nucleusstudio.io'", error: UndefinedColumn('column "talent_code" of relation "users" does not exist\nLINE 2:  SET talent_code=\'1aaaa\' WHERE email=\'ild+user@nucleusstudio...\n             ^\n')
2020-09-17 16:39:56,139 (51610/MainThread) pgcli.pgexecute ERROR - traceback: 'Traceback (most recent call last):\n  File "/usr/local/Cellar/pgcli/3.0.0/libexec/lib/python3.8/site-packages/pgcli/pgexecute.py", line 409, in run\n    yield self.execute_normal_sql(sql) + (sql, True, False)\n  File "/usr/local/Cellar/pgcli/3.0.0/libexec/lib/python3.8/site-packages/pgcli/pgexecute.py", line 444, in execute_normal_sql\n    cur.execute(split_sql)\npsycopg2.errors.UndefinedColumn: column "talent_code" of relation "users" does not exist\nLINE 2:  SET talent_code=\'1aaaa\' WHERE email=\'ild+user@nucleusstudio...\n             ^\n\n'
2020-09-24 17:20:53,838 (7664/MainThread) pgcli.main INFO - Default pager found in PAGER environment variable: "less"
2020-09-24 17:20:53,839 (7664/MainThread) pgcli.main WARNING - import keyring failed: ModuleNotFoundError("No module named 'keyring'").
2020-09-25 16:11:28,236 (7664/MainThread) pgcli.pgexecute ERROR - sql: 'SELECT * FROM public.users', error: OperationalError('SSL SYSCALL error: Operation timed out\n')
2020-09-25 16:11:28,239 (7664/MainThread) pgcli.pgexecute ERROR - traceback: 'Traceback (most recent call last):\n  File "/usr/local/Cellar/pgcli/3.0.0/libexec/lib/python3.8/site-packages/pgcli/pgexecute.py", line 409, in run\n    yield self.execute_normal_sql(sql) + (sql, True, False)\n  File "/usr/local/Cellar/pgcli/3.0.0/libexec/lib/python3.8/site-packages/pgcli/pgexecute.py", line 444, in execute_normal_sql\n    cur.execute(split_sql)\npsycopg2.OperationalError: SSL SYSCALL error: Operation timed out\n\n'
2020-09-25 16:11:30,593 (7664/MainThread) pgcli.pgexecute ERROR - sql: 'SELECT * FROM public.users', error: OperationalError('SSL SYSCALL error: EOF detected\n')
2020-09-25 16:11:30,593 (7664/MainThread) pgcli.pgexecute ERROR - traceback: 'Traceback (most recent call last):\n  File "/usr/local/Cellar/pgcli/3.0.0/libexec/lib/python3.8/site-packages/pgcli/pgexecute.py", line 409, in run\n    yield self.execute_normal_sql(sql) + (sql, True, False)\n  File "/usr/local/Cellar/pgcli/3.0.0/libexec/lib/python3.8/site-packages/pgcli/pgexecute.py", line 444, in execute_normal_sql\n    cur.execute(split_sql)\npsycopg2.OperationalError: SSL SYSCALL error: EOF detected\n\n'
2020-09-25 16:11:30,593 (7664/MainThread) pgcli.main ERROR - sql: 'SELECT * FROM public.users', error: OperationalError('SSL SYSCALL error: EOF detected\n')
2020-09-25 16:11:30,601 (7664/MainThread) pgcli.main ERROR - traceback: 'Traceback (most recent call last):\n  File "/usr/local/Cellar/pgcli/3.0.0/libexec/lib/python3.8/site-packages/pgcli/main.py", line 634, in execute_command\n    output, query = self._evaluate_command(text)\n  File "/usr/local/Cellar/pgcli/3.0.0/libexec/lib/python3.8/site-packages/pgcli/main.py", line 880, in _evaluate_command\n    for title, cur, headers, status, sql, success, is_special in res:\n  File "/usr/local/Cellar/pgcli/3.0.0/libexec/lib/python3.8/site-packages/pgcli/pgexecute.py", line 409, in run\n    yield self.execute_normal_sql(sql) + (sql, True, False)\n  File "/usr/local/Cellar/pgcli/3.0.0/libexec/lib/python3.8/site-packages/pgcli/pgexecute.py", line 444, in execute_normal_sql\n    cur.execute(split_sql)\npsycopg2.OperationalError: SSL SYSCALL error: EOF detected\n\n'
2020-09-29 17:56:27,836 (46243/MainThread) pgcli.main INFO - Default pager found in PAGER environment variable: "less"
2020-09-29 17:56:27,837 (46243/MainThread) pgcli.main WARNING - import keyring failed: ModuleNotFoundError("No module named 'keyring'").
2020-10-02 15:04:40,951 (51783/MainThread) pgcli.main INFO - Default pager found in PAGER environment variable: "less"
2020-10-02 15:04:40,952 (51783/MainThread) pgcli.main WARNING - import keyring failed: ModuleNotFoundError("No module named 'keyring'").
2020-10-02 15:07:25,680 (51783/MainThread) pgcli.pgexecute ERROR - sql: "UPDATE public.talent_profiles SET status='inprogress' WHERE id=' 08e9f40e-3020-4de4-bad9-89a5fca6897b'", error: InvalidTextRepresentation('invalid input syntax for type uuid: " 08e9f40e-3020-4de4-bad9-89a5fca6897b"\nLINE 1: ....talent_profiles SET status=\'inprogress\' WHERE id=\' 08e9f40e...\n                                                             ^\n')
2020-10-02 15:07:25,688 (51783/MainThread) pgcli.pgexecute ERROR - traceback: 'Traceback (most recent call last):\n  File "/usr/local/Cellar/pgcli/3.0.0/libexec/lib/python3.8/site-packages/pgcli/pgexecute.py", line 409, in run\n    yield self.execute_normal_sql(sql) + (sql, True, False)\n  File "/usr/local/Cellar/pgcli/3.0.0/libexec/lib/python3.8/site-packages/pgcli/pgexecute.py", line 444, in execute_normal_sql\n    cur.execute(split_sql)\npsycopg2.errors.InvalidTextRepresentation: invalid input syntax for type uuid: " 08e9f40e-3020-4de4-bad9-89a5fca6897b"\nLINE 1: ....talent_profiles SET status=\'inprogress\' WHERE id=\' 08e9f40e...\n                                                             ^\n\n'
2020-10-02 15:07:29,633 (51783/MainThread) pgcli.pgexecute ERROR - sql: "UPDATE public.talent_profiles SET status='inprogress' WHERE id='08e9f40e-3020-4de4-bad9-89a5fca6897b'", error: InvalidTextRepresentation('invalid input value for enum talent_profiles_status_enum: "inprogress"\nLINE 1: UPDATE public.talent_profiles SET status=\'inprogress\' WHERE ...\n                                                 ^\n')
2020-10-02 15:07:29,634 (51783/MainThread) pgcli.pgexecute ERROR - traceback: 'Traceback (most recent call last):\n  File "/usr/local/Cellar/pgcli/3.0.0/libexec/lib/python3.8/site-packages/pgcli/pgexecute.py", line 409, in run\n    yield self.execute_normal_sql(sql) + (sql, True, False)\n  File "/usr/local/Cellar/pgcli/3.0.0/libexec/lib/python3.8/site-packages/pgcli/pgexecute.py", line 444, in execute_normal_sql\n    cur.execute(split_sql)\npsycopg2.errors.InvalidTextRepresentation: invalid input value for enum talent_profiles_status_enum: "inprogress"\nLINE 1: UPDATE public.talent_profiles SET status=\'inprogress\' WHERE ...\n                                                 ^\n\n'
2020-10-02 15:07:41,649 (51783/MainThread) pgcli.pgexecute ERROR - sql: "UPDATE public.talent_profiles SET status='inprogress' WHERE id='08e9f40e-3020-4de4-bad9-89a5fca6897b'", error: InvalidTextRepresentation('invalid input value for enum talent_profiles_status_enum: "inprogress"\nLINE 1: UPDATE public.talent_profiles SET status=\'inprogress\' WHERE ...\n                                                 ^\n')
2020-10-02 15:07:41,649 (51783/MainThread) pgcli.pgexecute ERROR - traceback: 'Traceback (most recent call last):\n  File "/usr/local/Cellar/pgcli/3.0.0/libexec/lib/python3.8/site-packages/pgcli/pgexecute.py", line 409, in run\n    yield self.execute_normal_sql(sql) + (sql, True, False)\n  File "/usr/local/Cellar/pgcli/3.0.0/libexec/lib/python3.8/site-packages/pgcli/pgexecute.py", line 444, in execute_normal_sql\n    cur.execute(split_sql)\npsycopg2.errors.InvalidTextRepresentation: invalid input value for enum talent_profiles_status_enum: "inprogress"\nLINE 1: UPDATE public.talent_profiles SET status=\'inprogress\' WHERE ...\n                                                 ^\n\n'
2020-10-02 23:06:02,743 (31691/MainThread) pgcli.main INFO - Default pager found in PAGER environment variable: "less"
2020-10-02 23:06:02,744 (31691/MainThread) pgcli.main WARNING - import keyring failed: ModuleNotFoundError("No module named 'keyring'").
2020-10-04 11:56:24,162 (96244/MainThread) pgcli.main INFO - Default pager found in PAGER environment variable: "less"
2020-10-04 11:56:24,163 (96244/MainThread) pgcli.main WARNING - import keyring failed: ModuleNotFoundError("No module named 'keyring'").
2020-10-04 11:56:28,343 (96244/MainThread) pgcli.main ERROR - traceback: 'Traceback (most recent call last):\n  File "/usr/local/Cellar/pgcli/3.0.0/libexec/lib/python3.8/site-packages/pgcli/main.py", line 549, in connect\n    pgexecute = PGExecute(database, user, passwd, host, port, dsn, **kwargs)\n  File "/usr/local/Cellar/pgcli/3.0.0/libexec/lib/python3.8/site-packages/pgcli/pgexecute.py", line 214, in __init__\n    self.connect(database, user, password, host, port, dsn, **kwargs)\n  File "/usr/local/Cellar/pgcli/3.0.0/libexec/lib/python3.8/site-packages/pgcli/pgexecute.py", line 254, in connect\n    conn = psycopg2.connect(**conn_params)\n  File "/usr/local/Cellar/pgcli/3.0.0/libexec/lib/python3.8/site-packages/psycopg2/__init__.py", line 127, in connect\n    conn = _connect(dsn, connection_factory=connection_factory, **kwasync)\n  File "/usr/local/Cellar/pgcli/3.0.0/libexec/lib/python3.8/site-packages/pgcli/pgexecute.py", line 39, in _wait_select\n    state = conn.poll()\npsycopg2.OperationalError: fe_sendauth: no password supplied\n\n\nDuring handling of the above exception, another exception occurred:\n\nTraceback (most recent call last):\n  File "/usr/local/Cellar/pgcli/3.0.0/libexec/lib/python3.8/site-packages/click/termui.py", line 129, in prompt_func\n    return f("")\n  File "/usr/local/Cellar/pgcli/3.0.0/libexec/lib/python3.8/site-packages/click/termui.py", line 54, in hidden_prompt_func\n    return getpass.getpass(prompt)\n  File "/usr/local/opt/python@3.8/Frameworks/Python.framework/Versions/3.8/lib/python3.8/getpass.py", line 77, in unix_getpass\n    passwd = _raw_input(prompt, stream, input=input)\n  File "/usr/local/opt/python@3.8/Frameworks/Python.framework/Versions/3.8/lib/python3.8/getpass.py", line 146, in _raw_input\n    line = input.readline()\nKeyboardInterrupt\n\nDuring handling of the above exception, another exception occurred:\n\nTraceback (most recent call last):\n  File "/usr/local/Cellar/pgcli/3.0.0/libexec/lib/python3.8/site-packages/pgcli/main.py", line 552, in connect\n    passwd = click.prompt(\n  File "/usr/local/Cellar/pgcli/3.0.0/libexec/lib/python3.8/site-packages/click/termui.py", line 147, in prompt\n    value = prompt_func(prompt)\n  File "/usr/local/Cellar/pgcli/3.0.0/libexec/lib/python3.8/site-packages/click/termui.py", line 136, in prompt_func\n    raise Abort()\nclick.exceptions.Abort\n'
2020-10-04 11:56:49,509 (96697/MainThread) pgcli.main INFO - Default pager found in PAGER environment variable: "less"
2020-10-04 11:56:49,510 (96697/MainThread) pgcli.main WARNING - import keyring failed: ModuleNotFoundError("No module named 'keyring'").
2020-10-04 11:57:03,230 (96847/MainThread) pgcli.main INFO - Default pager found in PAGER environment variable: "less"
2020-10-04 11:57:03,231 (96847/MainThread) pgcli.main WARNING - import keyring failed: ModuleNotFoundError("No module named 'keyring'").
2020-10-04 11:57:04,904 (96847/MainThread) pgcli.main ERROR - traceback: 'Traceback (most recent call last):\n  File "/usr/local/Cellar/pgcli/3.0.0/libexec/lib/python3.8/site-packages/pgcli/main.py", line 562, in connect\n    raise e\n  File "/usr/local/Cellar/pgcli/3.0.0/libexec/lib/python3.8/site-packages/pgcli/main.py", line 549, in connect\n    pgexecute = PGExecute(database, user, passwd, host, port, dsn, **kwargs)\n  File "/usr/local/Cellar/pgcli/3.0.0/libexec/lib/python3.8/site-packages/pgcli/pgexecute.py", line 214, in __init__\n    self.connect(database, user, password, host, port, dsn, **kwargs)\n  File "/usr/local/Cellar/pgcli/3.0.0/libexec/lib/python3.8/site-packages/pgcli/pgexecute.py", line 254, in connect\n    conn = psycopg2.connect(**conn_params)\n  File "/usr/local/Cellar/pgcli/3.0.0/libexec/lib/python3.8/site-packages/psycopg2/__init__.py", line 127, in connect\n    conn = _connect(dsn, connection_factory=connection_factory, **kwasync)\n  File "/usr/local/Cellar/pgcli/3.0.0/libexec/lib/python3.8/site-packages/pgcli/pgexecute.py", line 39, in _wait_select\n    state = conn.poll()\npsycopg2.OperationalError: fe_sendauth: no password supplied\n\n'
2020-10-04 11:57:21,832 (97085/MainThread) pgcli.main INFO - Default pager found in PAGER environment variable: "less"
2020-10-04 11:57:21,832 (97085/MainThread) pgcli.main WARNING - import keyring failed: ModuleNotFoundError("No module named 'keyring'").
2020-10-04 11:57:39,965 (97322/MainThread) pgcli.main INFO - Default pager found in PAGER environment variable: "less"
2020-10-04 11:57:39,965 (97322/MainThread) pgcli.main WARNING - import keyring failed: ModuleNotFoundError("No module named 'keyring'").
2020-10-04 11:57:44,927 (97385/MainThread) pgcli.main INFO - Default pager found in PAGER environment variable: "less"
2020-10-04 11:57:44,927 (97385/MainThread) pgcli.main WARNING - import keyring failed: ModuleNotFoundError("No module named 'keyring'").
2020-10-04 11:57:46,454 (97385/MainThread) pgcli.main ERROR - traceback: 'Traceback (most recent call last):\n  File "/usr/local/Cellar/pgcli/3.0.0/libexec/lib/python3.8/site-packages/pgcli/main.py", line 562, in connect\n    raise e\n  File "/usr/local/Cellar/pgcli/3.0.0/libexec/lib/python3.8/site-packages/pgcli/main.py", line 549, in connect\n    pgexecute = PGExecute(database, user, passwd, host, port, dsn, **kwargs)\n  File "/usr/local/Cellar/pgcli/3.0.0/libexec/lib/python3.8/site-packages/pgcli/pgexecute.py", line 214, in __init__\n    self.connect(database, user, password, host, port, dsn, **kwargs)\n  File "/usr/local/Cellar/pgcli/3.0.0/libexec/lib/python3.8/site-packages/pgcli/pgexecute.py", line 254, in connect\n    conn = psycopg2.connect(**conn_params)\n  File "/usr/local/Cellar/pgcli/3.0.0/libexec/lib/python3.8/site-packages/psycopg2/__init__.py", line 127, in connect\n    conn = _connect(dsn, connection_factory=connection_factory, **kwasync)\n  File "/usr/local/Cellar/pgcli/3.0.0/libexec/lib/python3.8/site-packages/pgcli/pgexecute.py", line 39, in _wait_select\n    state = conn.poll()\npsycopg2.OperationalError: fe_sendauth: no password supplied\n\n'
2020-10-04 11:57:51,103 (97537/MainThread) pgcli.main INFO - Default pager found in PAGER environment variable: "less"
2020-10-04 11:57:51,104 (97537/MainThread) pgcli.main WARNING - import keyring failed: ModuleNotFoundError("No module named 'keyring'").
2020-10-04 12:04:16,851 (97537/MainThread) pgcli.pgexecute ERROR - sql: 'SELECT * FROM experiences where id=f159a29d-4165-42c5-9d80-f8c77150af0e', error: SyntaxError('syntax error at or near "c5"\nLINE 1: ...ELECT * FROM experiences where id=f159a29d-4165-42c5-9d80-f8...\n                                                             ^\n')
2020-10-04 12:04:16,859 (97537/MainThread) pgcli.pgexecute ERROR - traceback: 'Traceback (most recent call last):\n  File "/usr/local/Cellar/pgcli/3.0.0/libexec/lib/python3.8/site-packages/pgcli/pgexecute.py", line 409, in run\n    yield self.execute_normal_sql(sql) + (sql, True, False)\n  File "/usr/local/Cellar/pgcli/3.0.0/libexec/lib/python3.8/site-packages/pgcli/pgexecute.py", line 444, in execute_normal_sql\n    cur.execute(split_sql)\npsycopg2.errors.SyntaxError: syntax error at or near "c5"\nLINE 1: ...ELECT * FROM experiences where id=f159a29d-4165-42c5-9d80-f8...\n                                                             ^\n\n'
2020-10-05 10:23:14,468 (97537/MainThread) pgcli.pgexecute ERROR - sql: "UPDATE public.users\n  SET talent_profile_id=null  WHERE email='ild+user@nucleusstudio.io'", error: OperationalError('server closed the connection unexpectedly\n\tThis probably means the server terminated abnormally\n\tbefore or while processing the request.\n')
2020-10-05 10:23:14,470 (97537/MainThread) pgcli.pgexecute ERROR - traceback: 'Traceback (most recent call last):\n  File "/usr/local/Cellar/pgcli/3.0.0/libexec/lib/python3.8/site-packages/pgcli/pgexecute.py", line 409, in run\n    yield self.execute_normal_sql(sql) + (sql, True, False)\n  File "/usr/local/Cellar/pgcli/3.0.0/libexec/lib/python3.8/site-packages/pgcli/pgexecute.py", line 444, in execute_normal_sql\n    cur.execute(split_sql)\npsycopg2.OperationalError: server closed the connection unexpectedly\n\tThis probably means the server terminated abnormally\n\tbefore or while processing the request.\n\n'
2020-10-05 10:23:14,470 (97537/MainThread) pgcli.main ERROR - sql: "UPDATE public.users\n  SET talent_profile_id=null  WHERE email='ild+user@nucleusstudio.io'", error: OperationalError('server closed the connection unexpectedly\n\tThis probably means the server terminated abnormally\n\tbefore or while processing the request.\n')
2020-10-05 10:23:14,471 (97537/MainThread) pgcli.main ERROR - traceback: 'Traceback (most recent call last):\n  File "/usr/local/Cellar/pgcli/3.0.0/libexec/lib/python3.8/site-packages/pgcli/main.py", line 634, in execute_command\n    output, query = self._evaluate_command(text)\n  File "/usr/local/Cellar/pgcli/3.0.0/libexec/lib/python3.8/site-packages/pgcli/main.py", line 880, in _evaluate_command\n    for title, cur, headers, status, sql, success, is_special in res:\n  File "/usr/local/Cellar/pgcli/3.0.0/libexec/lib/python3.8/site-packages/pgcli/pgexecute.py", line 409, in run\n    yield self.execute_normal_sql(sql) + (sql, True, False)\n  File "/usr/local/Cellar/pgcli/3.0.0/libexec/lib/python3.8/site-packages/pgcli/pgexecute.py", line 444, in execute_normal_sql\n    cur.execute(split_sql)\npsycopg2.OperationalError: server closed the connection unexpectedly\n\tThis probably means the server terminated abnormally\n\tbefore or while processing the request.\n\n'
2020-10-08 17:23:09,128 (86608/MainThread) pgcli.main INFO - Default pager found in PAGER environment variable: "less"
2020-10-08 17:23:09,129 (86608/MainThread) pgcli.main WARNING - import keyring failed: ModuleNotFoundError("No module named 'keyring'").
2020-10-08 17:24:47,738 (88879/MainThread) pgcli.main INFO - Default pager found in PAGER environment variable: "less"
2020-10-08 17:24:47,739 (88879/MainThread) pgcli.main WARNING - import keyring failed: ModuleNotFoundError("No module named 'keyring'").
2020-10-08 17:25:10,785 (88879/MainThread) pgcli.pgexecute ERROR - sql: "DELETE FROM experiences where id='e8f688cc-2e2a-4d15-b613-d15d270263f'", error: InvalidTextRepresentation('invalid input syntax for type uuid: "e8f688cc-2e2a-4d15-b613-d15d270263f"\nLINE 1: DELETE FROM experiences where id=\'e8f688cc-2e2a-4d15-b613-d1...\n                                         ^\n')
2020-10-08 17:25:10,788 (88879/MainThread) pgcli.pgexecute ERROR - traceback: 'Traceback (most recent call last):\n  File "/usr/local/Cellar/pgcli/3.0.0/libexec/lib/python3.8/site-packages/pgcli/pgexecute.py", line 409, in run\n    yield self.execute_normal_sql(sql) + (sql, True, False)\n  File "/usr/local/Cellar/pgcli/3.0.0/libexec/lib/python3.8/site-packages/pgcli/pgexecute.py", line 444, in execute_normal_sql\n    cur.execute(split_sql)\npsycopg2.errors.InvalidTextRepresentation: invalid input syntax for type uuid: "e8f688cc-2e2a-4d15-b613-d15d270263f"\nLINE 1: DELETE FROM experiences where id=\'e8f688cc-2e2a-4d15-b613-d1...\n                                         ^\n\n'
2020-10-08 17:25:24,409 (88879/MainThread) pgcli.pgexecute ERROR - sql: "DELETE FROM experiences where id='e8f688cc-2e2a-4d15-b613-d15d270263f'", error: InvalidTextRepresentation('invalid input syntax for type uuid: "e8f688cc-2e2a-4d15-b613-d15d270263f"\nLINE 1: DELETE FROM experiences where id=\'e8f688cc-2e2a-4d15-b613-d1...\n                                         ^\n')
2020-10-08 17:25:24,410 (88879/MainThread) pgcli.pgexecute ERROR - traceback: 'Traceback (most recent call last):\n  File "/usr/local/Cellar/pgcli/3.0.0/libexec/lib/python3.8/site-packages/pgcli/pgexecute.py", line 409, in run\n    yield self.execute_normal_sql(sql) + (sql, True, False)\n  File "/usr/local/Cellar/pgcli/3.0.0/libexec/lib/python3.8/site-packages/pgcli/pgexecute.py", line 444, in execute_normal_sql\n    cur.execute(split_sql)\npsycopg2.errors.InvalidTextRepresentation: invalid input syntax for type uuid: "e8f688cc-2e2a-4d15-b613-d15d270263f"\nLINE 1: DELETE FROM experiences where id=\'e8f688cc-2e2a-4d15-b613-d1...\n                                         ^\n\n'
2020-10-08 17:25:35,691 (88879/MainThread) pgcli.pgexecute ERROR - sql: 'DELETE FROM experiences where id="e8f688cc-2e2a-4d15-b613-d15d270263f"', error: UndefinedColumn('column "e8f688cc-2e2a-4d15-b613-d15d270263f" does not exist\nLINE 1: DELETE FROM experiences where id="e8f688cc-2e2a-4d15-b613-d1...\n                                         ^\n')
2020-10-08 17:25:35,697 (88879/MainThread) pgcli.pgexecute ERROR - traceback: 'Traceback (most recent call last):\n  File "/usr/local/Cellar/pgcli/3.0.0/libexec/lib/python3.8/site-packages/pgcli/pgexecute.py", line 409, in run\n    yield self.execute_normal_sql(sql) + (sql, True, False)\n  File "/usr/local/Cellar/pgcli/3.0.0/libexec/lib/python3.8/site-packages/pgcli/pgexecute.py", line 444, in execute_normal_sql\n    cur.execute(split_sql)\npsycopg2.errors.UndefinedColumn: column "e8f688cc-2e2a-4d15-b613-d15d270263f" does not exist\nLINE 1: DELETE FROM experiences where id="e8f688cc-2e2a-4d15-b613-d1...\n                                         ^\n\n'
2020-10-08 17:25:48,790 (88879/MainThread) pgcli.pgexecute ERROR - sql: 'DELETE FROM experiences where id="e8f688cc-2e2a-4d15-b613-d15d270263fb"', error: UndefinedColumn('column "e8f688cc-2e2a-4d15-b613-d15d270263fb" does not exist\nLINE 1: DELETE FROM experiences where id="e8f688cc-2e2a-4d15-b613-d1...\n                                         ^\n')
2020-10-08 17:25:48,790 (88879/MainThread) pgcli.pgexecute ERROR - traceback: 'Traceback (most recent call last):\n  File "/usr/local/Cellar/pgcli/3.0.0/libexec/lib/python3.8/site-packages/pgcli/pgexecute.py", line 409, in run\n    yield self.execute_normal_sql(sql) + (sql, True, False)\n  File "/usr/local/Cellar/pgcli/3.0.0/libexec/lib/python3.8/site-packages/pgcli/pgexecute.py", line 444, in execute_normal_sql\n    cur.execute(split_sql)\npsycopg2.errors.UndefinedColumn: column "e8f688cc-2e2a-4d15-b613-d15d270263fb" does not exist\nLINE 1: DELETE FROM experiences where id="e8f688cc-2e2a-4d15-b613-d1...\n                                         ^\n\n'
2020-10-08 17:26:09,247 (88879/MainThread) pgcli.pgexecute ERROR - sql: 'DELETE FROM experiences as test where test.id="e8f688cc-2e2a-4d15-b613-d15d270263fb"', error: UndefinedColumn('column "e8f688cc-2e2a-4d15-b613-d15d270263fb" does not exist\nLINE 1: DELETE FROM experiences as test where test.id="e8f688cc-2e2a...\n                                                      ^\n')
2020-10-08 17:26:09,248 (88879/MainThread) pgcli.pgexecute ERROR - traceback: 'Traceback (most recent call last):\n  File "/usr/local/Cellar/pgcli/3.0.0/libexec/lib/python3.8/site-packages/pgcli/pgexecute.py", line 409, in run\n    yield self.execute_normal_sql(sql) + (sql, True, False)\n  File "/usr/local/Cellar/pgcli/3.0.0/libexec/lib/python3.8/site-packages/pgcli/pgexecute.py", line 444, in execute_normal_sql\n    cur.execute(split_sql)\npsycopg2.errors.UndefinedColumn: column "e8f688cc-2e2a-4d15-b613-d15d270263fb" does not exist\nLINE 1: DELETE FROM experiences as test where test.id="e8f688cc-2e2a...\n                                                      ^\n\n'
2020-10-08 17:26:48,687 (88879/MainThread) pgcli.pgexecute ERROR - sql: 'DELETE FROM experiences where id="e8f688cc-2e2a-4d15-b613-d15d270263fb"', error: UndefinedColumn('column "e8f688cc-2e2a-4d15-b613-d15d270263fb" does not exist\nLINE 1: DELETE FROM experiences where id="e8f688cc-2e2a-4d15-b613-d1...\n                                         ^\n')
2020-10-08 17:26:48,689 (88879/MainThread) pgcli.pgexecute ERROR - traceback: 'Traceback (most recent call last):\n  File "/usr/local/Cellar/pgcli/3.0.0/libexec/lib/python3.8/site-packages/pgcli/pgexecute.py", line 409, in run\n    yield self.execute_normal_sql(sql) + (sql, True, False)\n  File "/usr/local/Cellar/pgcli/3.0.0/libexec/lib/python3.8/site-packages/pgcli/pgexecute.py", line 444, in execute_normal_sql\n    cur.execute(split_sql)\npsycopg2.errors.UndefinedColumn: column "e8f688cc-2e2a-4d15-b613-d15d270263fb" does not exist\nLINE 1: DELETE FROM experiences where id="e8f688cc-2e2a-4d15-b613-d1...\n                                         ^\n\n'
2020-10-08 17:27:09,266 (88879/MainThread) pgcli.pgexecute ERROR - sql: "DELETE FROM experiences where id='e8f688cc-2e2a-4d15-b613-d15d270263fb'", error: ForeignKeyViolation('update or delete on table "experiences" violates foreign key constraint "FK_6c33f7aacf32c072222ef4c0cae" on table "time-ranges"\nDETAIL:  Key (id)=(e8f688cc-2e2a-4d15-b613-d15d270263fb) is still referenced from table "time-ranges".\n')
2020-10-08 17:27:09,271 (88879/MainThread) pgcli.pgexecute ERROR - traceback: 'Traceback (most recent call last):\n  File "/usr/local/Cellar/pgcli/3.0.0/libexec/lib/python3.8/site-packages/pgcli/pgexecute.py", line 409, in run\n    yield self.execute_normal_sql(sql) + (sql, True, False)\n  File "/usr/local/Cellar/pgcli/3.0.0/libexec/lib/python3.8/site-packages/pgcli/pgexecute.py", line 444, in execute_normal_sql\n    cur.execute(split_sql)\npsycopg2.errors.ForeignKeyViolation: update or delete on table "experiences" violates foreign key constraint "FK_6c33f7aacf32c072222ef4c0cae" on table "time-ranges"\nDETAIL:  Key (id)=(e8f688cc-2e2a-4d15-b613-d15d270263fb) is still referenced from table "time-ranges".\n\n'
2020-10-09 15:20:38,673 (90422/MainThread) pgcli.main INFO - Default pager found in PAGER environment variable: "less"
2020-10-09 15:20:38,673 (90422/MainThread) pgcli.main WARNING - import keyring failed: ModuleNotFoundError("No module named 'keyring'").
2020-10-09 15:22:00,392 (90422/MainThread) pgcli.pgexecute ERROR - sql: "SELECT account_status from public.talent_profiles where id='6bb26093-840b-4c87-9abd-d7a5a093b7b'", error: InvalidTextRepresentation('invalid input syntax for type uuid: "6bb26093-840b-4c87-9abd-d7a5a093b7b"\nLINE 1: ...count_status from public.talent_profiles where id=\'6bb26093-...\n                                                             ^\n')
2020-10-09 15:22:00,400 (90422/MainThread) pgcli.pgexecute ERROR - traceback: 'Traceback (most recent call last):\n  File "/usr/local/Cellar/pgcli/3.0.0/libexec/lib/python3.8/site-packages/pgcli/pgexecute.py", line 409, in run\n    yield self.execute_normal_sql(sql) + (sql, True, False)\n  File "/usr/local/Cellar/pgcli/3.0.0/libexec/lib/python3.8/site-packages/pgcli/pgexecute.py", line 444, in execute_normal_sql\n    cur.execute(split_sql)\npsycopg2.errors.InvalidTextRepresentation: invalid input syntax for type uuid: "6bb26093-840b-4c87-9abd-d7a5a093b7b"\nLINE 1: ...count_status from public.talent_profiles where id=\'6bb26093-...\n                                                             ^\n\n'
2020-10-09 15:22:10,026 (90422/MainThread) pgcli.pgexecute ERROR - sql: 'SELECT account_status from public.talent_profiles where id="6bb26093-840b-4c87-9abd-d7a5a093b7bb"', error: UndefinedColumn('column "6bb26093-840b-4c87-9abd-d7a5a093b7bb" does not exist\nLINE 1: ...count_status from public.talent_profiles where id="6bb26093-...\n                                                             ^\n')
2020-10-09 15:22:10,027 (90422/MainThread) pgcli.pgexecute ERROR - traceback: 'Traceback (most recent call last):\n  File "/usr/local/Cellar/pgcli/3.0.0/libexec/lib/python3.8/site-packages/pgcli/pgexecute.py", line 409, in run\n    yield self.execute_normal_sql(sql) + (sql, True, False)\n  File "/usr/local/Cellar/pgcli/3.0.0/libexec/lib/python3.8/site-packages/pgcli/pgexecute.py", line 444, in execute_normal_sql\n    cur.execute(split_sql)\npsycopg2.errors.UndefinedColumn: column "6bb26093-840b-4c87-9abd-d7a5a093b7bb" does not exist\nLINE 1: ...count_status from public.talent_profiles where id="6bb26093-...\n                                                             ^\n\n'
2020-10-09 17:16:32,122 (90422/MainThread) pgcli.pgexecute ERROR - sql: "SELECT * FROM experiences WHERE id='b191b847-3745-48cc-b658-69ae9c4ef7a'", error: InvalidTextRepresentation('invalid input syntax for type uuid: "b191b847-3745-48cc-b658-69ae9c4ef7a"\nLINE 1: SELECT * FROM experiences WHERE id=\'b191b847-3745-48cc-b658-...\n                                           ^\n')
2020-10-09 17:16:32,129 (90422/MainThread) pgcli.pgexecute ERROR - traceback: 'Traceback (most recent call last):\n  File "/usr/local/Cellar/pgcli/3.0.0/libexec/lib/python3.8/site-packages/pgcli/pgexecute.py", line 409, in run\n    yield self.execute_normal_sql(sql) + (sql, True, False)\n  File "/usr/local/Cellar/pgcli/3.0.0/libexec/lib/python3.8/site-packages/pgcli/pgexecute.py", line 444, in execute_normal_sql\n    cur.execute(split_sql)\npsycopg2.errors.InvalidTextRepresentation: invalid input syntax for type uuid: "b191b847-3745-48cc-b658-69ae9c4ef7a"\nLINE 1: SELECT * FROM experiences WHERE id=\'b191b847-3745-48cc-b658-...\n                                           ^\n\n'
2020-10-09 17:17:10,034 (90422/MainThread) pgcli.pgexecute ERROR - sql: "SELECT schedule_time FROM experiences WHERE id='b191b847-3745-48cc-b658-69ae9c4ef7a'", error: InvalidTextRepresentation('invalid input syntax for type uuid: "b191b847-3745-48cc-b658-69ae9c4ef7a"\nLINE 1: SELECT schedule_time FROM experiences WHERE id=\'b191b847-374...\n                                                       ^\n')
2020-10-09 17:17:10,034 (90422/MainThread) pgcli.pgexecute ERROR - traceback: 'Traceback (most recent call last):\n  File "/usr/local/Cellar/pgcli/3.0.0/libexec/lib/python3.8/site-packages/pgcli/pgexecute.py", line 409, in run\n    yield self.execute_normal_sql(sql) + (sql, True, False)\n  File "/usr/local/Cellar/pgcli/3.0.0/libexec/lib/python3.8/site-packages/pgcli/pgexecute.py", line 444, in execute_normal_sql\n    cur.execute(split_sql)\npsycopg2.errors.InvalidTextRepresentation: invalid input syntax for type uuid: "b191b847-3745-48cc-b658-69ae9c4ef7a"\nLINE 1: SELECT schedule_time FROM experiences WHERE id=\'b191b847-374...\n                                                       ^\n\n'
2020-10-09 17:17:18,935 (90422/MainThread) pgcli.pgexecute ERROR - sql: "SELECT identified FROM experiences WHERE id='b191b847-3745-48cc-b658-69ae9c4ef7a'", error: UndefinedColumn('column "identified" does not exist\nLINE 1: SELECT identified FROM experiences WHERE id=\'b191b847-3745-4...\n               ^\n')
2020-10-09 17:17:18,936 (90422/MainThread) pgcli.pgexecute ERROR - traceback: 'Traceback (most recent call last):\n  File "/usr/local/Cellar/pgcli/3.0.0/libexec/lib/python3.8/site-packages/pgcli/pgexecute.py", line 409, in run\n    yield self.execute_normal_sql(sql) + (sql, True, False)\n  File "/usr/local/Cellar/pgcli/3.0.0/libexec/lib/python3.8/site-packages/pgcli/pgexecute.py", line 444, in execute_normal_sql\n    cur.execute(split_sql)\npsycopg2.errors.UndefinedColumn: column "identified" does not exist\nLINE 1: SELECT identified FROM experiences WHERE id=\'b191b847-3745-4...\n               ^\n\n'
2020-10-09 17:17:24,551 (90422/MainThread) pgcli.pgexecute ERROR - sql: "SELECT * FROM experiences WHERE id='b191b847-3745-48cc-b658-69ae9c4ef7a'", error: InvalidTextRepresentation('invalid input syntax for type uuid: "b191b847-3745-48cc-b658-69ae9c4ef7a"\nLINE 1: SELECT * FROM experiences WHERE id=\'b191b847-3745-48cc-b658-...\n                                           ^\n')
2020-10-09 17:17:24,552 (90422/MainThread) pgcli.pgexecute ERROR - traceback: 'Traceback (most recent call last):\n  File "/usr/local/Cellar/pgcli/3.0.0/libexec/lib/python3.8/site-packages/pgcli/pgexecute.py", line 409, in run\n    yield self.execute_normal_sql(sql) + (sql, True, False)\n  File "/usr/local/Cellar/pgcli/3.0.0/libexec/lib/python3.8/site-packages/pgcli/pgexecute.py", line 444, in execute_normal_sql\n    cur.execute(split_sql)\npsycopg2.errors.InvalidTextRepresentation: invalid input syntax for type uuid: "b191b847-3745-48cc-b658-69ae9c4ef7a"\nLINE 1: SELECT * FROM experiences WHERE id=\'b191b847-3745-48cc-b658-...\n                                           ^\n\n'
2020-10-09 17:17:54,906 (90422/MainThread) pgcli.pgexecute ERROR - sql: "DELETE FROM experiences where id='b191b847-3745-48cc-b658-69ae9c4ef7af'", error: ForeignKeyViolation('update or delete on table "experiences" violates foreign key constraint "FK_6c33f7aacf32c072222ef4c0cae" on table "time-ranges"\nDETAIL:  Key (id)=(b191b847-3745-48cc-b658-69ae9c4ef7af) is still referenced from table "time-ranges".\n')
2020-10-09 17:17:54,907 (90422/MainThread) pgcli.pgexecute ERROR - traceback: 'Traceback (most recent call last):\n  File "/usr/local/Cellar/pgcli/3.0.0/libexec/lib/python3.8/site-packages/pgcli/pgexecute.py", line 409, in run\n    yield self.execute_normal_sql(sql) + (sql, True, False)\n  File "/usr/local/Cellar/pgcli/3.0.0/libexec/lib/python3.8/site-packages/pgcli/pgexecute.py", line 444, in execute_normal_sql\n    cur.execute(split_sql)\npsycopg2.errors.ForeignKeyViolation: update or delete on table "experiences" violates foreign key constraint "FK_6c33f7aacf32c072222ef4c0cae" on table "time-ranges"\nDETAIL:  Key (id)=(b191b847-3745-48cc-b658-69ae9c4ef7af) is still referenced from table "time-ranges".\n\n'
2020-10-09 17:18:14,814 (90422/MainThread) pgcli.pgexecute ERROR - sql: 'DELET FROM "time-ranges" where id=\'b191b847-3745-48cc-b658-69ae9c4ef7af\'', error: SyntaxError('syntax error at or near "DELET"\nLINE 1: DELET FROM "time-ranges" where id=\'b191b847-3745-48cc-b658-6...\n        ^\n')
2020-10-09 17:18:14,815 (90422/MainThread) pgcli.pgexecute ERROR - traceback: 'Traceback (most recent call last):\n  File "/usr/local/Cellar/pgcli/3.0.0/libexec/lib/python3.8/site-packages/pgcli/pgexecute.py", line 409, in run\n    yield self.execute_normal_sql(sql) + (sql, True, False)\n  File "/usr/local/Cellar/pgcli/3.0.0/libexec/lib/python3.8/site-packages/pgcli/pgexecute.py", line 444, in execute_normal_sql\n    cur.execute(split_sql)\npsycopg2.errors.SyntaxError: syntax error at or near "DELET"\nLINE 1: DELET FROM "time-ranges" where id=\'b191b847-3745-48cc-b658-6...\n        ^\n\n'
2020-10-09 17:18:26,737 (90422/MainThread) pgcli.pgexecute ERROR - sql: "DELETE FROM experiences where id='b191b847-3745-48cc-b658-69ae9c4ef7af'", error: ForeignKeyViolation('update or delete on table "experiences" violates foreign key constraint "FK_6c33f7aacf32c072222ef4c0cae" on table "time-ranges"\nDETAIL:  Key (id)=(b191b847-3745-48cc-b658-69ae9c4ef7af) is still referenced from table "time-ranges".\n')
2020-10-09 17:18:26,738 (90422/MainThread) pgcli.pgexecute ERROR - traceback: 'Traceback (most recent call last):\n  File "/usr/local/Cellar/pgcli/3.0.0/libexec/lib/python3.8/site-packages/pgcli/pgexecute.py", line 409, in run\n    yield self.execute_normal_sql(sql) + (sql, True, False)\n  File "/usr/local/Cellar/pgcli/3.0.0/libexec/lib/python3.8/site-packages/pgcli/pgexecute.py", line 444, in execute_normal_sql\n    cur.execute(split_sql)\npsycopg2.errors.ForeignKeyViolation: update or delete on table "experiences" violates foreign key constraint "FK_6c33f7aacf32c072222ef4c0cae" on table "time-ranges"\nDETAIL:  Key (id)=(b191b847-3745-48cc-b658-69ae9c4ef7af) is still referenced from table "time-ranges".\n\n'
2020-10-09 17:19:09,251 (90422/MainThread) pgcli.pgexecute ERROR - sql: 'DELET FROM "time-ranges" where id=\'1974b760-d90f-4728-aedd-2c815f50821\'', error: SyntaxError('syntax error at or near "DELET"\nLINE 1: DELET FROM "time-ranges" where id=\'1974b760-d90f-4728-aedd-2...\n        ^\n')
2020-10-09 17:19:09,252 (90422/MainThread) pgcli.pgexecute ERROR - traceback: 'Traceback (most recent call last):\n  File "/usr/local/Cellar/pgcli/3.0.0/libexec/lib/python3.8/site-packages/pgcli/pgexecute.py", line 409, in run\n    yield self.execute_normal_sql(sql) + (sql, True, False)\n  File "/usr/local/Cellar/pgcli/3.0.0/libexec/lib/python3.8/site-packages/pgcli/pgexecute.py", line 444, in execute_normal_sql\n    cur.execute(split_sql)\npsycopg2.errors.SyntaxError: syntax error at or near "DELET"\nLINE 1: DELET FROM "time-ranges" where id=\'1974b760-d90f-4728-aedd-2...\n        ^\n\n'
2020-10-09 17:19:19,239 (90422/MainThread) pgcli.pgexecute ERROR - sql: 'DELETE FROM "time-ranges" where id=\'1974b760-d90f-4728-aedd-2c815f50821\'', error: InvalidTextRepresentation('invalid input syntax for type uuid: "1974b760-d90f-4728-aedd-2c815f50821"\nLINE 1: DELETE FROM "time-ranges" where id=\'1974b760-d90f-4728-aedd-...\n                                           ^\n')
2020-10-09 17:19:19,239 (90422/MainThread) pgcli.pgexecute ERROR - traceback: 'Traceback (most recent call last):\n  File "/usr/local/Cellar/pgcli/3.0.0/libexec/lib/python3.8/site-packages/pgcli/pgexecute.py", line 409, in run\n    yield self.execute_normal_sql(sql) + (sql, True, False)\n  File "/usr/local/Cellar/pgcli/3.0.0/libexec/lib/python3.8/site-packages/pgcli/pgexecute.py", line 444, in execute_normal_sql\n    cur.execute(split_sql)\npsycopg2.errors.InvalidTextRepresentation: invalid input syntax for type uuid: "1974b760-d90f-4728-aedd-2c815f50821"\nLINE 1: DELETE FROM "time-ranges" where id=\'1974b760-d90f-4728-aedd-...\n                                           ^\n\n'
